Workbook

Sheet Инструкция
A1: Выгрузка квартирографии — как получить отчёт
A3: Один раз: в Проигрывателе Dynamo выберите папку \\server\share\BIM\Dynamo\Выгрузка квартирографии.
A5: Каждый раз:
A6: 1. Закройте файлы Квартирография_*.xlsx.
A7: 2. Откройте модель ОВ нужного корпуса (связь АР загружена, модель сохранена).
A8: 3. Управление → Проигрыватель Dynamo → «Выгрузка_квартирографии» → Запуск. «Связь АР» оставьте пустым.
A9: 4. Откройте папку «Квартирография» рядом с моделью ОВ (для совместной работы — рядом с файлом-хранилищем) и файл Квартирография_K__.xlsx. Результат: листы «Типовые этажи» и «Таблица 1» (F9 при необходимости).
A11: Если ошибка:
A12: • Появился файл Квартирография_ОШИБКА.xlsx — в нём на листе «Выгрузка» причина и список связей. Загрузите связь АР или впишите часть её имени в поле «Связь АР» (если связей АР несколько).
A13: • Узел жёлтый с текстом «Закройте файл…» — закройте Excel и запустите снова. «Нет шаблона…» — верните Квартирография_ШАБЛОН.xlsx в папку скрипта. «Модель ОВ не сохранена / в облаке» — сохраните модель на сервере.
A14: • «ВНИМАНИЕ: нет параметров…» — поправьте имена параметров в блоке НАСТРОЙКИ узла «Выгрузка АР». Имена помещений — на листе «Настройки».

Sheet Типовые этажи
A1: =Настройки!B3 | C1: =IF(LEFT(INDIRECT("'Выгрузка'!A1")&"",6)="ОШИБКА","Ошибка выгрузки — см. лист Выгрузка","Квартир: "&COUNT(Квартиры!$K$2:$K$1501)&" Этажей: "&COUNT(A3:A82)&" Групп: "&MAX(B3:B82)&IF(Настройки!B4="да"," (с учётом типа)","")) | N1: =IF(Настройки!E5="","","Выгружено: "&Настройки!E5)
A2: Этаж | B2: Группа | C2: Кв. 1 | D2: Кв. 2 | E2: Кв. 3 | F2: Кв. 4 | G2: Кв. 5 | H2: Кв. 6 | I2: Кв. 7 | J2: Кв. 8 | K2: Кв. 9 | L2: Кв. 10 | M2: Кв. 11 | N2: Кв. 12 | O2: Кв. 13 | P2: Кв. 14 | Q2: Кв. 15 | R2: Ключ | S2: Этажи группы | U2: Группа | V2: Этажи | W2: Кол-во
A3: =IFERROR(MIN(Квартиры!$B$2:$B$1501)/(COUNT(Квартиры!$B$2:$B$1501)>0),"") | B3: =IF(A3="","",IF(COUNTIF(R$2:R2,R3)=0,MAX(B$2:B2)+1,INDEX(B$2:B2,MATCH(R3,R$2:R2,0)))) | C3: =IF($A3="","",IFERROR(IF(Настройки!$B$4="да",INDEX(Квартиры!$D$2:$D$1501,MATCH($A3*1000+1,Квартиры!$K$2:$K$1501,0))&" / ","")&INDEX(Квартиры!$H$2:$H$1501,MATCH($A3*1000+1,Квартиры!$K$2:$K$1501,0))&" СУ"&IF(INDEX(Квартиры!$I$2:$I$1501,MATCH($A3*1000+1,Квартиры!$K$2:$K$1501,0))>0," +У","")&IF(INDEX(Квартиры!$J$2:$J$1501,MATCH($A3*1000+1,Квартиры!$K$2:$K$1501,0))>0," +Г",""),"-")) | D3: =IF($A3="","",IFERROR(IF(Настройки!$B$4="да",INDEX(Квартиры!$D$2:$D$1501,MATCH($A3*1000+2,Квартиры!$K$2:$K$1501,0))&" / ","")&INDEX(Квартиры!$H$2:$H$1501,MATCH($A3*1000+2,Квартиры!$K$2:$K$1501,0))&" СУ"&IF(INDEX(Квартиры!$I$2:$I$1501,MATCH($A3*1000+2,Квартиры!$K$2:$K$1501,0))>0," +У","")&IF(INDEX(Квартиры!$J$2:$J$1501,MATCH($A3*1000+2,Квартиры!$K$2:$K$1501,0))>0," +Г",""),"-")) | E3: =IF($A3="","",IFERROR(IF(Настройки!$B$4="да",INDEX(Квартиры!$D$2:$D$1501,MATCH($A3*1000+3,Квартиры!$K$2:$K$1501,0))&" / ","")&INDEX(Квартиры!$H$2:$H$1501,MATCH($A3*1000+3,Квартиры!$K$2:$K$1501,0))&" СУ"&IF(INDEX(Квартиры!$I$2:$I$1501,MATCH($A3*1000+3,Квартиры!$K$2:$K$1501,0))>0," +У","")&IF(INDEX(Квартиры!$J$2:$J$1501,MATCH($A3*1000+3,Квартиры!$K$2:$K$1501,0))>0," +Г",""),"-")) | F3: =IF($A3="","",IFERROR(IF(Настройки!$B$4="да",INDEX(Квартиры!$D$2:$D$1501,MATCH($A3*1000+4,Квартиры!$K$2:$K$1501,0))&" / ","")&INDEX(Квартиры!$H$2:$H$1501,MATCH($A3*1000+4,Квартиры!$K$2:$K$1501,0))&" СУ"&IF(INDEX(Квартиры!$I$2:$I$1501,MATCH($A3*1000+4,Квартиры!$K$2:$K$1501,0))>0," +У","")&IF(INDEX(Квартиры!$J$2:$J$1501,MATCH($A3*1000+4,Квартиры!$K$2:$K$1501,0))>0," +Г",""),"-")) | G3: =IF($A3="","",IFERROR(IF(Настройки!$B$4="да",INDEX(Квартиры!$D$2:$D$1501,MATCH($A3*1000+5,Квартиры!$K$2:$K$1501,0))&" / ","")&INDEX(Квартиры!$H$2:$H$1501,MATCH($A3*1000+5,Квартиры!$K$2:$K$1501,0))&" СУ"&IF(INDEX(Квартиры!$I$2:$I$1501,MATCH($A3*1000+5,Квартиры!$K$2:$K$1501,0))>0," +У","")&IF(INDEX(Квартиры!$J$2:$J$1501,MATCH($A3*1000+5,Квартиры!$K$2:$K$1501,0))>0," +Г",""),"-")) | H3: =IF($A3="","",IFERROR(IF(Настройки!$B$4="да",INDEX(Квартиры!$D$2:$D$1501,MATCH($A3*1000+6,Квартиры!$K$2:$K$1501,0))&" / ","")&INDEX(Квартиры!$H$2:$H$1501,MATCH($A3*1000+6,Квартиры!$K$2:$K$1501,0))&" СУ"&IF(INDEX(Квартиры!$I$2:$I$1501,MATCH($A3*1000+6,Квартиры!$K$2:$K$1501,0))>0," +У","")&IF(INDEX(Квартиры!$J$2:$J$1501,MATCH($A3*1000+6,Квартиры!$K$2:$K$1501,0))>0," +Г",""),"-")) | I3: =IF($A3="","",IFERROR(IF(Настройки!$B$4="да",INDEX(Квартиры!$D$2:$D$1501,MATCH($A3*1000+7,Квартиры!$K$2:$K$1501,0))&" / ","")&INDEX(Квартиры!$H$2:$H$1501,MATCH($A3*1000+7,Квартиры!$K$2:$K$1501,0))&" СУ"&IF(INDEX(Квартиры!$I$2:$I$1501,MATCH($A3*1000+7,Квартиры!$K$2:$K$1501,0))>0," +У","")&IF(INDEX(Квартиры!$J$2:$J$1501,MATCH($A3*1000+7,Квартиры!$K$2:$K$1501,0))>0," +Г",""),"-")) | J3: =IF($A3="","",IFERROR(IF(Настройки!$B$4="да",INDEX(Квартиры!$D$2:$D$1501,MATCH($A3*1000+8,Квартиры!$K$2:$K$1501,0))&" / ","")&INDEX(Квартиры!$H$2:$H$1501,MATCH($A3*1000+8,Квартиры!$K$2:$K$1501,0))&" СУ"&IF(INDEX(Квартиры!$I$2:$I$1501,MATCH($A3*1000+8,Квартиры!$K$2:$K$1501,0))>0," +У","")&IF(INDEX(Квартиры!$J$2:$J$1501,MATCH($A3*1000+8,Квартиры!$K$2:$K$1501,0))>0," +Г",""),"-")) | K3: =IF($A3="","",IFERROR(IF(Настройки!$B$4="да",INDEX(Квартиры!$D$2:$D$1501,MATCH($A3*1000+9,Квартиры!$K$2:$K$1501,0))&" / ","")&INDEX(Квартиры!$H$2:$H$1501,MATCH($A3*1000+9,Квартиры!$K$2:$K$1501,0))&" СУ"&IF(INDEX(Квартиры!$I$2:$I$1501,MATCH($A3*1000+9,Квартиры!$K$2:$K$1501,0))>0," +У","")&IF(INDEX(Квартиры!$J$2:$J$1501,MATCH($A3*1000+9,Квартиры!$K$2:$K$1501,0))>0," +Г",""),"-")) | L3: =IF($A3="","",IFERROR(IF(Настройки!$B$4="да",INDEX(Квартиры!$D$2:$D$1501,MATCH($A3*1000+10,Квартиры!$K$2:$K$1501,0))&" / ","")&INDEX(Квартиры!$H$2:$H$1501,MATCH($A3*1000+10,Квартиры!$K$2:$K$1501,0))&" СУ"&IF(INDEX(Квартиры!$I$2:$I$1501,MATCH($A3*1000+10,Квартиры!$K$2:$K$1501,0))>0," +У","")&IF(INDEX(Квартиры!$J$2:$J$1501,MATCH($A3*1000+10,Квартиры!$K$2:$K$1501,0))>0," +Г",""),"-")) | M3: =IF($A3="","",IFERROR(IF(Настройки!$B$4="да",INDEX(Квартиры!$D$2:$D$1501,MATCH($A3*1000+11,Квартиры!$K$2:$K$1501,0))&" / ","")&INDEX(Квартиры!$H$2:$H$1501,MATCH($A3*1000+11,Квартиры!$K$2:$K$1501,0))&" СУ"&IF(INDEX(Квартиры!$I$2:$I$1501,MATCH($A3*1000+11,Квартиры!$K$2:$K$1501,0))>0," +У","")&IF(INDEX(Квартиры!$J$2:$J$1501,MATCH($A3*1000+11,Квартиры!$K$2:$K$1501,0))>0," +Г",""),"-")) | N3: =IF($A3="","",IFERROR(IF(Настройки!$B$4="да",INDEX(Квартиры!$D$2:$D$1501,MATCH($A3*1000+12,Квартиры!$K$2:$K$1501,0))&" / ","")&INDEX(Квартиры!$H$2:$H$1501,MATCH($A3*1000+12,Квартиры!$K$2:$K$1501,0))&" СУ"&IF(INDEX(Квартиры!$I$2:$I$1501,MATCH($A3*1000+12,Квартиры!$K$2:$K$1501,0))>0," +У","")&IF(INDEX(Квартиры!$J$2:$J$1501,MATCH($A3*1000+12,Квартиры!$K$2:$K$1501,0))>0," +Г",""),"-")) | O3: =IF($A3="","",IFERROR(IF(Настройки!$B$4="да",INDEX(Квартиры!$D$2:$D$1501,MATCH($A3*1000+13,Квартиры!$K$2:$K$1501,0))&" / ","")&INDEX(Квартиры!$H$2:$H$1501,MATCH($A3*1000+13,Квартиры!$K$2:$K$1501,0))&" СУ"&IF(INDEX(Квартиры!$I$2:$I$1501,MATCH($A3*1000+13,Квартиры!$K$2:$K$1501,0))>0," +У","")&IF(INDEX(Квартиры!$J$2:$J$1501,MATCH($A3*1000+13,Квартиры!$K$2:$K$1501,0))>0," +Г",""),"-")) | P3: =IF($A3="","",IFERROR(IF(Настройки!$B$4="да",INDEX(Квартиры!$D$2:$D$1501,MATCH($A3*1000+14,Квартиры!$K$2:$K$1501,0))&" / ","")&INDEX(Квартиры!$H$2:$H$1501,MATCH($A3*1000+14,Квартиры!$K$2:$K$1501,0))&" СУ"&IF(INDEX(Квартиры!$I$2:$I$1501,MATCH($A3*1000+14,Квартиры!$K$2:$K$1501,0))>0," +У","")&IF(INDEX(Квартиры!$J$2:$J$1501,MATCH($A3*1000+14,Квартиры!$K$2:$K$1501,0))>0," +Г",""),"-")) | Q3: =IF($A3="","",IFERROR(IF(Настройки!$B$4="да",INDEX(Квартиры!$D$2:$D$1501,MATCH($A3*1000+15,Квартиры!$K$2:$K$1501,0))&" / ","")&INDEX(Квартиры!$H$2:$H$1501,MATCH($A3*1000+15,Квартиры!$K$2:$K$1501,0))&" СУ"&IF(INDEX(Квартиры!$I$2:$I$1501,MATCH($A3*1000+15,Квартиры!$K$2:$K$1501,0))>0," +У","")&IF(INDEX(Квартиры!$J$2:$J$1501,MATCH($A3*1000+15,Квартиры!$K$2:$K$1501,0))>0," +Г",""),"-")) | R3: =IF(A3="","",C3&"|"&D3&"|"&E3&"|"&F3&"|"&G3&"|"&H3&"|"&I3&"|"&J3&"|"&K3&"|"&L3&"|"&M3&"|"&N3&"|"&O3&"|"&P3&"|"&Q3) | S3: =IF(A3="","",IFERROR(LOOKUP(2,1/(B$2:B2=B3),S$2:S2)&", ","")&A3) | U3: =IF(1>MAX(B$3:B$82),"",1) | V3: =IF(U3="","",LOOKUP(2,1/(B$3:B$82=U3),S$3:S$82)) | W3: =IF(U3="","",COUNTIF(B$3:B$82,U3))
A4: =IFERROR(IF(A3="","",SMALL(Квартиры!$B$2:$B$1501,COUNTIF(Квартиры!$B$2:$B$1501,"<="&A3)+1)),"") | B4: =IF(A4="","",IF(COUNTIF(R$2:R3,R4)=0,MAX(B$2:B3)+1,INDEX(B$2:B3,MATCH(R4,R$2:R3,0)))) | C4: =IF($A4="","",IFERROR(IF(Настройки!$B$4="да",INDEX(Квартиры!$D$2:$D$1501,MATCH($A4*1000+1,Квартиры!$K$2:$K$1501,0))&" / ","")&INDEX(Квартиры!$H$2:$H$1501,MATCH($A4*1000+1,Квартиры!$K$2:$K$1501,0))&" СУ"&IF(INDEX(Квартиры!$I$2:$I$1501,MATCH($A4*1000+1,Квартиры!$K$2:$K$1501,0))>0," +У","")&IF(INDEX(Квартиры!$J$2:$J$1501,MATCH($A4*1000+1,Квартиры!$K$2:$K$1501,0))>0," +Г",""),"-")) | D4: =IF($A4="","",IFERROR(IF(Настройки!$B$4="да",INDEX(Квартиры!$D$2:$D$1501,MATCH($A4*1000+2,Квартиры!$K$2:$K$1501,0))&" / ","")&INDEX(Квартиры!$H$2:$H$1501,MATCH($A4*1000+2,Квартиры!$K$2:$K$1501,0))&" СУ"&IF(INDEX(Квартиры!$I$2:$I$1501,MATCH($A4*1000+2,Квартиры!$K$2:$K$1501,0))>0," +У","")&IF(INDEX(Квартиры!$J$2:$J$1501,MATCH($A4*1000+2,Квартиры!$K$2:$K$1501,0))>0," +Г",""),"-")) | E4: =IF($A4="","",IFERROR(IF(Настройки!$B$4="да",INDEX(Квартиры!$D$2:$D$1501,MATCH($A4*1000+3,Квартиры!$K$2:$K$1501,0))&" / ","")&INDEX(Квартиры!$H$2:$H$1501,MATCH($A4*1000+3,Квартиры!$K$2:$K$1501,0))&" СУ"&IF(INDEX(Квартиры!$I$2:$I$1501,MATCH($A4*1000+3,Квартиры!$K$2:$K$1501,0))>0," +У","")&IF(INDEX(Квартиры!$J$2:$J$1501,MATCH($A4*1000+3,Квартиры!$K$2:$K$1501,0))>0," +Г",""),"-")) | F4: =IF($A4="","",IFERROR(IF(Настройки!$B$4="да",INDEX(Квартиры!$D$2:$D$1501,MATCH($A4*1000+4,Квартиры!$K$2:$K$1501,0))&" / ","")&INDEX(Квартиры!$H$2:$H$1501,MATCH($A4*1000+4,Квартиры!$K$2:$K$1501,0))&" СУ"&IF(INDEX(Квартиры!$I$2:$I$1501,MATCH($A4*1000+4,Квартиры!$K$2:$K$1501,0))>0," +У","")&IF(INDEX(Квартиры!$J$2:$J$1501,MATCH($A4*1000+4,Квартиры!$K$2:$K$1501,0))>0," +Г",""),"-")) | G4: =IF($A4="","",IFERROR(IF(Настройки!$B$4="да",INDEX(Квартиры!$D$2:$D$1501,MATCH($A4*1000+5,Квартиры!$K$2:$K$1501,0))&" / ","")&INDEX(Квартиры!$H$2:$H$1501,MATCH($A4*1000+5,Квартиры!$K$2:$K$1501,0))&" СУ"&IF(INDEX(Квартиры!$I$2:$I$1501,MATCH($A4*1000+5,Квартиры!$K$2:$K$1501,0))>0," +У","")&IF(INDEX(Квартиры!$J$2:$J$1501,MATCH($A4*1000+5,Квартиры!$K$2:$K$1501,0))>0," +Г",""),"-")) | H4: =IF($A4="","",IFERROR(IF(Настройки!$B$4="да",INDEX(Квартиры!$D$2:$D$1501,MATCH($A4*1000+6,Квартиры!$K$2:$K$1501,0))&" / ","")&INDEX(Квартиры!$H$2:$H$1501,MATCH($A4*1000+6,Квартиры!$K$2:$K$1501,0))&" СУ"&IF(INDEX(Квартиры!$I$2:$I$1501,MATCH($A4*1000+6,Квартиры!$K$2:$K$1501,0))>0," +У","")&IF(INDEX(Квартиры!$J$2:$J$1501,MATCH($A4*1000+6,Квартиры!$K$2:$K$1501,0))>0," +Г",""),"-")) | I4: =IF($A4="","",IFERROR(IF(Настройки!$B$4="да",INDEX(Квартиры!$D$2:$D$1501,MATCH($A4*1000+7,Квартиры!$K$2:$K$1501,0))&" / ","")&INDEX(Квартиры!$H$2:$H$1501,MATCH($A4*1000+7,Квартиры!$K$2:$K$1501,0))&" СУ"&IF(INDEX(Квартиры!$I$2:$I$1501,MATCH($A4*1000+7,Квартиры!$K$2:$K$1501,0))>0," +У","")&IF(INDEX(Квартиры!$J$2:$J$1501,MATCH($A4*1000+7,Квартиры!$K$2:$K$1501,0))>0," +Г",""),"-")) | J4: =IF($A4="","",IFERROR(IF(Настройки!$B$4="да",INDEX(Квартиры!$D$2:$D$1501,MATCH($A4*1000+8,Квартиры!$K$2:$K$1501,0))&" / ","")&INDEX(Квартиры!$H$2:$H$1501,MATCH($A4*1000+8,Квартиры!$K$2:$K$1501,0))&" СУ"&IF(INDEX(Квартиры!$I$2:$I$1501,MATCH($A4*1000+8,Квартиры!$K$2:$K$1501,0))>0," +У","")&IF(INDEX(Квартиры!$J$2:$J$1501,MATCH($A4*1000+8,Квартиры!$K$2:$K$1501,0))>0," +Г",""),"-")) | K4: =IF($A4="","",IFERROR(IF(Настройки!$B$4="да",INDEX(Квартиры!$D$2:$D$1501,MATCH($A4*1000+9,Квартиры!$K$2:$K$1501,0))&" / ","")&INDEX(Квартиры!$H$2:$H$1501,MATCH($A4*1000+9,Квартиры!$K$2:$K$1501,0))&" СУ"&IF(INDEX(Квартиры!$I$2:$I$1501,MATCH($A4*1000+9,Квартиры!$K$2:$K$1501,0))>0," +У","")&IF(INDEX(Квартиры!$J$2:$J$1501,MATCH($A4*1000+9,Квартиры!$K$2:$K$1501,0))>0," +Г",""),"-")) | L4: =IF($A4="","",IFERROR(IF(Настройки!$B$4="да",INDEX(Квартиры!$D$2:$D$1501,MATCH($A4*1000+10,Квартиры!$K$2:$K$1501,0))&" / ","")&INDEX(Квартиры!$H$2:$H$1501,MATCH($A4*1000+10,Квартиры!$K$2:$K$1501,0))&" СУ"&IF(INDEX(Квартиры!$I$2:$I$1501,MATCH($A4*1000+10,Квартиры!$K$2:$K$1501,0))>0," +У","")&IF(INDEX(Квартиры!$J$2:$J$1501,MATCH($A4*1000+10,Квартиры!$K$2:$K$1501,0))>0," +Г",""),"-")) | M4: =IF($A4="","",IFERROR(IF(Настройки!$B$4="да",INDEX(Квартиры!$D$2:$D$1501,MATCH($A4*1000+11,Квартиры!$K$2:$K$1501,0))&" / ","")&INDEX(Квартиры!$H$2:$H$1501,MATCH($A4*1000+11,Квартиры!$K$2:$K$1501,0))&" СУ"&IF(INDEX(Квартиры!$I$2:$I$1501,MATCH($A4*1000+11,Квартиры!$K$2:$K$1501,0))>0," +У","")&IF(INDEX(Квартиры!$J$2:$J$1501,MATCH($A4*1000+11,Квартиры!$K$2:$K$1501,0))>0," +Г",""),"-")) | N4: =IF($A4="","",IFERROR(IF(Настройки!$B$4="да",INDEX(Квартиры!$D$2:$D$1501,MATCH($A4*1000+12,Квартиры!$K$2:$K$1501,0))&" / ","")&INDEX(Квартиры!$H$2:$H$1501,MATCH($A4*1000+12,Квартиры!$K$2:$K$1501,0))&" СУ"&IF(INDEX(Квартиры!$I$2:$I$1501,MATCH($A4*1000+12,Квартиры!$K$2:$K$1501,0))>0," +У","")&IF(INDEX(Квартиры!$J$2:$J$1501,MATCH($A4*1000+12,Квартиры!$K$2:$K$1501,0))>0," +Г",""),"-")) | O4: =IF($A4="","",IFERROR(IF(Настройки!$B$4="да",INDEX(Квартиры!$D$2:$D$1501,MATCH($A4*1000+13,Квартиры!$K$2:$K$1501,0))&" / ","")&INDEX(Квартиры!$H$2:$H$1501,MATCH($A4*1000+13,Квартиры!$K$2:$K$1501,0))&" СУ"&IF(INDEX(Квартиры!$I$2:$I$1501,MATCH($A4*1000+13,Квартиры!$K$2:$K$1501,0))>0," +У","")&IF(INDEX(Квартиры!$J$2:$J$1501,MATCH($A4*1000+13,Квартиры!$K$2:$K$1501,0))>0," +Г",""),"-")) | P4: =IF($A4="","",IFERROR(IF(Настройки!$B$4="да",INDEX(Квартиры!$D$2:$D$1501,MATCH($A4*1000+14,Квартиры!$K$2:$K$1501,0))&" / ","")&INDEX(Квартиры!$H$2:$H$1501,MATCH($A4*1000+14,Квартиры!$K$2:$K$1501,0))&" СУ"&IF(INDEX(Квартиры!$I$2:$I$1501,MATCH($A4*1000+14,Квартиры!$K$2:$K$1501,0))>0," +У","")&IF(INDEX(Квартиры!$J$2:$J$1501,MATCH($A4*1000+14,Квартиры!$K$2:$K$1501,0))>0," +Г",""),"-")) | Q4: =IF($A4="","",IFERROR(IF(Настройки!$B$4="да",INDEX(Квартиры!$D$2:$D$1501,MATCH($A4*1000+15,Квартиры!$K$2:$K$1501,0))&" / ","")&INDEX(Квартиры!$H$2:$H$1501,MATCH($A4*1000+15,Квартиры!$K$2:$K$1501,0))&" СУ"&IF(INDEX(Квартиры!$I$2:$I$1501,MATCH($A4*1000+15,Квартиры!$K$2:$K$1501,0))>0," +У","")&IF(INDEX(Квартиры!$J$2:$J$1501,MATCH($A4*1000+15,Квартиры!$K$2:$K$1501,0))>0," +Г",""),"-")) | R4: =IF(A4="","",C4&"|"&D4&"|"&E4&"|"&F4&"|"&G4&"|"&H4&"|"&I4&"|"&J4&"|"&K4&"|"&L4&"|"&M4&"|"&N4&"|"&O4&"|"&P4&"|"&Q4) | S4: =IF(A4="","",IFERROR(LOOKUP(2,1/(B$2:B3=B4),S$2:S3)&", ","")&A4) | U4: =IF(2>MAX(B$3:B$82),"",2) | V4: =IF(U4="","",LOOKUP(2,1/(B$3:B$82=U4),S$3:S$82)) | W4: =IF(U4="","",COUNTIF(B$3:B$82,U4))
A5: =IFERROR(IF(A4="","",SMALL(Квартиры!$B$2:$B$1501,COUNTIF(Квартиры!$B$2:$B$1501,"<="&A4)+1)),"") | B5: =IF(A5="","",IF(COUNTIF(R$2:R4,R5)=0,MAX(B$2:B4)+1,INDEX(B$2:B4,MATCH(R5,R$2:R4,0)))) | C5: =IF($A5="","",IFERROR(IF(Настройки!$B$4="да",INDEX(Квартиры!$D$2:$D$1501,MATCH($A5*1000+1,Квартиры!$K$2:$K$1501,0))&" / ","")&INDEX(Квартиры!$H$2:$H$1501,MATCH($A5*1000+1,Квартиры!$K$2:$K$1501,0))&" СУ"&IF(INDEX(Квартиры!$I$2:$I$1501,MATCH($A5*1000+1,Квартиры!$K$2:$K$1501,0))>0," +У","")&IF(INDEX(Квартиры!$J$2:$J$1501,MATCH($A5*1000+1,Квартиры!$K$2:$K$1501,0))>0," +Г",""),"-")) | D5: =IF($A5="","",IFERROR(IF(Настройки!$B$4="да",INDEX(Квартиры!$D$2:$D$1501,MATCH($A5*1000+2,Квартиры!$K$2:$K$1501,0))&" / ","")&INDEX(Квартиры!$H$2:$H$1501,MATCH($A5*1000+2,Квартиры!$K$2:$K$1501,0))&" СУ"&IF(INDEX(Квартиры!$I$2:$I$1501,MATCH($A5*1000+2,Квартиры!$K$2:$K$1501,0))>0," +У","")&IF(INDEX(Квартиры!$J$2:$J$1501,MATCH($A5*1000+2,Квартиры!$K$2:$K$1501,0))>0," +Г",""),"-")) | E5: =IF($A5="","",IFERROR(IF(Настройки!$B$4="да",INDEX(Квартиры!$D$2:$D$1501,MATCH($A5*1000+3,Квартиры!$K$2:$K$1501,0))&" / ","")&INDEX(Квартиры!$H$2:$H$1501,MATCH($A5*1000+3,Квартиры!$K$2:$K$1501,0))&" СУ"&IF(INDEX(Квартиры!$I$2:$I$1501,MATCH($A5*1000+3,Квартиры!$K$2:$K$1501,0))>0," +У","")&IF(INDEX(Квартиры!$J$2:$J$1501,MATCH($A5*1000+3,Квартиры!$K$2:$K$1501,0))>0," +Г",""),"-")) | F5: =IF($A5="","",IFERROR(IF(Настройки!$B$4="да",INDEX(Квартиры!$D$2:$D$1501,MATCH($A5*1000+4,Квартиры!$K$2:$K$1501,0))&" / ","")&INDEX(Квартиры!$H$2:$H$1501,MATCH($A5*1000+4,Квартиры!$K$2:$K$1501,0))&" СУ"&IF(INDEX(Квартиры!$I$2:$I$1501,MATCH($A5*1000+4,Квартиры!$K$2:$K$1501,0))>0," +У","")&IF(INDEX(Квартиры!$J$2:$J$1501,MATCH($A5*1000+4,Квартиры!$K$2:$K$1501,0))>0," +Г",""),"-")) | G5: =IF($A5="","",IFERROR(IF(Настройки!$B$4="да",INDEX(Квартиры!$D$2:$D$1501,MATCH($A5*1000+5,Квартиры!$K$2:$K$1501,0))&" / ","")&INDEX(Квартиры!$H$2:$H$1501,MATCH($A5*1000+5,Квартиры!$K$2:$K$1501,0))&" СУ"&IF(INDEX(Квартиры!$I$2:$I$1501,MATCH($A5*1000+5,Квартиры!$K$2:$K$1501,0))>0," +У","")&IF(INDEX(Квартиры!$J$2:$J$1501,MATCH($A5*1000+5,Квартиры!$K$2:$K$1501,0))>0," +Г",""),"-")) | H5: =IF($A5="","",IFERROR(IF(Настройки!$B$4="да",INDEX(Квартиры!$D$2:$D$1501,MATCH($A5*1000+6,Квартиры!$K$2:$K$1501,0))&" / ","")&INDEX(Квартиры!$H$2:$H$1501,MATCH($A5*1000+6,Квартиры!$K$2:$K$1501,0))&" СУ"&IF(INDEX(Квартиры!$I$2:$I$1501,MATCH($A5*1000+6,Квартиры!$K$2:$K$1501,0))>0," +У","")&IF(INDEX(Квартиры!$J$2:$J$1501,MATCH($A5*1000+6,Квартиры!$K$2:$K$1501,0))>0," +Г",""),"-")) | I5: =IF($A5="","",IFERROR(IF(Настройки!$B$4="да",INDEX(Квартиры!$D$2:$D$1501,MATCH($A5*1000+7,Квартиры!$K$2:$K$1501,0))&" / ","")&INDEX(Квартиры!$H$2:$H$1501,MATCH($A5*1000+7,Квартиры!$K$2:$K$1501,0))&" СУ"&IF(INDEX(Квартиры!$I$2:$I$1501,MATCH($A5*1000+7,Квартиры!$K$2:$K$1501,0))>0," +У","")&IF(INDEX(Квартиры!$J$2:$J$1501,MATCH($A5*1000+7,Квартиры!$K$2:$K$1501,0))>0," +Г",""),"-")) | J5: =IF($A5="","",IFERROR(IF(Настройки!$B$4="да",INDEX(Квартиры!$D$2:$D$1501,MATCH($A5*1000+8,Квартиры!$K$2:$K$1501,0))&" / ","")&INDEX(Квартиры!$H$2:$H$1501,MATCH($A5*1000+8,Квартиры!$K$2:$K$1501,0))&" СУ"&IF(INDEX(Квартиры!$I$2:$I$1501,MATCH($A5*1000+8,Квартиры!$K$2:$K$1501,0))>0," +У","")&IF(INDEX(Квартиры!$J$2:$J$1501,MATCH($A5*1000+8,Квартиры!$K$2:$K$1501,0))>0," +Г",""),"-")) | K5: =IF($A5="","",IFERROR(IF(Настройки!$B$4="да",INDEX(Квартиры!$D$2:$D$1501,MATCH($A5*1000+9,Квартиры!$K$2:$K$1501,0))&" / ","")&INDEX(Квартиры!$H$2:$H$1501,MATCH($A5*1000+9,Квартиры!$K$2:$K$1501,0))&" СУ"&IF(INDEX(Квартиры!$I$2:$I$1501,MATCH($A5*1000+9,Квартиры!$K$2:$K$1501,0))>0," +У","")&IF(INDEX(Квартиры!$J$2:$J$1501,MATCH($A5*1000+9,Квартиры!$K$2:$K$1501,0))>0," +Г",""),"-")) | L5: =IF($A5="","",IFERROR(IF(Настройки!$B$4="да",INDEX(Квартиры!$D$2:$D$1501,MATCH($A5*1000+10,Квартиры!$K$2:$K$1501,0))&" / ","")&INDEX(Квартиры!$H$2:$H$1501,MATCH($A5*1000+10,Квартиры!$K$2:$K$1501,0))&" СУ"&IF(INDEX(Квартиры!$I$2:$I$1501,MATCH($A5*1000+10,Квартиры!$K$2:$K$1501,0))>0," +У","")&IF(INDEX(Квартиры!$J$2:$J$1501,MATCH($A5*1000+10,Квартиры!$K$2:$K$1501,0))>0," +Г",""),"-")) | M5: =IF($A5="","",IFERROR(IF(Настройки!$B$4="да",INDEX(Квартиры!$D$2:$D$1501,MATCH($A5*1000+11,Квартиры!$K$2:$K$1501,0))&" / ","")&INDEX(Квартиры!$H$2:$H$1501,MATCH($A5*1000+11,Квартиры!$K$2:$K$1501,0))&" СУ"&IF(INDEX(Квартиры!$I$2:$I$1501,MATCH($A5*1000+11,Квартиры!$K$2:$K$1501,0))>0," +У","")&IF(INDEX(Квартиры!$J$2:$J$1501,MATCH($A5*1000+11,Квартиры!$K$2:$K$1501,0))>0," +Г",""),"-")) | N5: =IF($A5="","",IFERROR(IF(Настройки!$B$4="да",INDEX(Квартиры!$D$2:$D$1501,MATCH($A5*1000+12,Квартиры!$K$2:$K$1501,0))&" / ","")&INDEX(Квартиры!$H$2:$H$1501,MATCH($A5*1000+12,Квартиры!$K$2:$K$1501,0))&" СУ"&IF(INDEX(Квартиры!$I$2:$I$1501,MATCH($A5*1000+12,Квартиры!$K$2:$K$1501,0))>0," +У","")&IF(INDEX(Квартиры!$J$2:$J$1501,MATCH($A5*1000+12,Квартиры!$K$2:$K$1501,0))>0," +Г",""),"-")) | O5: =IF($A5="","",IFERROR(IF(Настройки!$B$4="да",INDEX(Квартиры!$D$2:$D$1501,MATCH($A5*1000+13,Квартиры!$K$2:$K$1501,0))&" / ","")&INDEX(Квартиры!$H$2:$H$1501,MATCH($A5*1000+13,Квартиры!$K$2:$K$1501,0))&" СУ"&IF(INDEX(Квартиры!$I$2:$I$1501,MATCH($A5*1000+13,Квартиры!$K$2:$K$1501,0))>0," +У","")&IF(INDEX(Квартиры!$J$2:$J$1501,MATCH($A5*1000+13,Квартиры!$K$2:$K$1501,0))>0," +Г",""),"-")) | P5: =IF($A5="","",IFERROR(IF(Настройки!$B$4="да",INDEX(Квартиры!$D$2:$D$1501,MATCH($A5*1000+14,Квартиры!$K$2:$K$1501,0))&" / ","")&INDEX(Квартиры!$H$2:$H$1501,MATCH($A5*1000+14,Квартиры!$K$2:$K$1501,0))&" СУ"&IF(INDEX(Квартиры!$I$2:$I$1501,MATCH($A5*1000+14,Квартиры!$K$2:$K$1501,0))>0," +У","")&IF(INDEX(Квартиры!$J$2:$J$1501,MATCH($A5*1000+14,Квартиры!$K$2:$K$1501,0))>0," +Г",""),"-")) | Q5: =IF($A5="","",IFERROR(IF(Настройки!$B$4="да",INDEX(Квартиры!$D$2:$D$1501,MATCH($A5*1000+15,Квартиры!$K$2:$K$1501,0))&" / ","")&INDEX(Квартиры!$H$2:$H$1501,MATCH($A5*1000+15,Квартиры!$K$2:$K$1501,0))&" СУ"&IF(INDEX(Квартиры!$I$2:$I$1501,MATCH($A5*1000+15,Квартиры!$K$2:$K$1501,0))>0," +У","")&IF(INDEX(Квартиры!$J$2:$J$1501,MATCH($A5*1000+15,Квартиры!$K$2:$K$1501,0))>0," +Г",""),"-")) | R5: =IF(A5="","",C5&"|"&D5&"|"&E5&"|"&F5&"|"&G5&"|"&H5&"|"&I5&"|"&J5&"|"&K5&"|"&L5&"|"&M5&"|"&N5&"|"&O5&"|"&P5&"|"&Q5) | S5: =IF(A5="","",IFERROR(LOOKUP(2,1/(B$2:B4=B5),S$2:S4)&", ","")&A5) | U5: =IF(3>MAX(B$3:B$82),"",3) | V5: =IF(U5="","",LOOKUP(2,1/(B$3:B$82=U5),S$3:S$82)) | W5: =IF(U5="","",COUNTIF(B$3:B$82,U5))
A6: =IFERROR(IF(A5="","",SMALL(Квартиры!$B$2:$B$1501,COUNTIF(Квартиры!$B$2:$B$1501,"<="&A5)+1)),"") | B6: =IF(A6="","",IF(COUNTIF(R$2:R5,R6)=0,MAX(B$2:B5)+1,INDEX(B$2:B5,MATCH(R6,R$2:R5,0)))) | C6: =IF($A6="","",IFERROR(IF(Настройки!$B$4="да",INDEX(Квартиры!$D$2:$D$1501,MATCH($A6*1000+1,Квартиры!$K$2:$K$1501,0))&" / ","")&INDEX(Квартиры!$H$2:$H$1501,MATCH($A6*1000+1,Квартиры!$K$2:$K$1501,0))&" СУ"&IF(INDEX(Квартиры!$I$2:$I$1501,MATCH($A6*1000+1,Квартиры!$K$2:$K$1501,0))>0," +У","")&IF(INDEX(Квартиры!$J$2:$J$1501,MATCH($A6*1000+1,Квартиры!$K$2:$K$1501,0))>0," +Г",""),"-")) | D6: =IF($A6="","",IFERROR(IF(Настройки!$B$4="да",INDEX(Квартиры!$D$2:$D$1501,MATCH($A6*1000+2,Квартиры!$K$2:$K$1501,0))&" / ","")&INDEX(Квартиры!$H$2:$H$1501,MATCH($A6*1000+2,Квартиры!$K$2:$K$1501,0))&" СУ"&IF(INDEX(Квартиры!$I$2:$I$1501,MATCH($A6*1000+2,Квартиры!$K$2:$K$1501,0))>0," +У","")&IF(INDEX(Квартиры!$J$2:$J$1501,MATCH($A6*1000+2,Квартиры!$K$2:$K$1501,0))>0," +Г",""),"-")) | E6: =IF($A6="","",IFERROR(IF(Настройки!$B$4="да",INDEX(Квартиры!$D$2:$D$1501,MATCH($A6*1000+3,Квартиры!$K$2:$K$1501,0))&" / ","")&INDEX(Квартиры!$H$2:$H$1501,MATCH($A6*1000+3,Квартиры!$K$2:$K$1501,0))&" СУ"&IF(INDEX(Квартиры!$I$2:$I$1501,MATCH($A6*1000+3,Квартиры!$K$2:$K$1501,0))>0," +У","")&IF(INDEX(Квартиры!$J$2:$J$1501,MATCH($A6*1000+3,Квартиры!$K$2:$K$1501,0))>0," +Г",""),"-")) | F6: =IF($A6="","",IFERROR(IF(Настройки!$B$4="да",INDEX(Квартиры!$D$2:$D$1501,MATCH($A6*1000+4,Квартиры!$K$2:$K$1501,0))&" / ","")&INDEX(Квартиры!$H$2:$H$1501,MATCH($A6*1000+4,Квартиры!$K$2:$K$1501,0))&" СУ"&IF(INDEX(Квартиры!$I$2:$I$1501,MATCH($A6*1000+4,Квартиры!$K$2:$K$1501,0))>0," +У","")&IF(INDEX(Квартиры!$J$2:$J$1501,MATCH($A6*1000+4,Квартиры!$K$2:$K$1501,0))>0," +Г",""),"-")) | G6: =IF($A6="","",IFERROR(IF(Настройки!$B$4="да",INDEX(Квартиры!$D$2:$D$1501,MATCH($A6*1000+5,Квартиры!$K$2:$K$1501,0))&" / ","")&INDEX(Квартиры!$H$2:$H$1501,MATCH($A6*1000+5,Квартиры!$K$2:$K$1501,0))&" СУ"&IF(INDEX(Квартиры!$I$2:$I$1501,MATCH($A6*1000+5,Квартиры!$K$2:$K$1501,0))>0," +У","")&IF(INDEX(Квартиры!$J$2:$J$1501,MATCH($A6*1000+5,Квартиры!$K$2:$K$1501,0))>0," +Г",""),"-")) | H6: =IF($A6="","",IFERROR(IF(Настройки!$B$4="да",INDEX(Квартиры!$D$2:$D$1501,MATCH($A6*1000+6,Квартиры!$K$2:$K$1501,0))&" / ","")&INDEX(Квартиры!$H$2:$H$1501,MATCH($A6*1000+6,Квартиры!$K$2:$K$1501,0))&" СУ"&IF(INDEX(Квартиры!$I$2:$I$1501,MATCH($A6*1000+6,Квартиры!$K$2:$K$1501,0))>0," +У","")&IF(INDEX(Квартиры!$J$2:$J$1501,MATCH($A6*1000+6,Квартиры!$K$2:$K$1501,0))>0," +Г",""),"-")) | I6: =IF($A6="","",IFERROR(IF(Настройки!$B$4="да",INDEX(Квартиры!$D$2:$D$1501,MATCH($A6*1000+7,Квартиры!$K$2:$K$1501,0))&" / ","")&INDEX(Квартиры!$H$2:$H$1501,MATCH($A6*1000+7,Квартиры!$K$2:$K$1501,0))&" СУ"&IF(INDEX(Квартиры!$I$2:$I$1501,MATCH($A6*1000+7,Квартиры!$K$2:$K$1501,0))>0," +У","")&IF(INDEX(Квартиры!$J$2:$J$1501,MATCH($A6*1000+7,Квартиры!$K$2:$K$1501,0))>0," +Г",""),"-")) | J6: =IF($A6="","",IFERROR(IF(Настройки!$B$4="да",INDEX(Квартиры!$D$2:$D$1501,MATCH($A6*1000+8,Квартиры!$K$2:$K$1501,0))&" / ","")&INDEX(Квартиры!$H$2:$H$1501,MATCH($A6*1000+8,Квартиры!$K$2:$K$1501,0))&" СУ"&IF(INDEX(Квартиры!$I$2:$I$1501,MATCH($A6*1000+8,Квартиры!$K$2:$K$1501,0))>0," +У","")&IF(INDEX(Квартиры!$J$2:$J$1501,MATCH($A6*1000+8,Квартиры!$K$2:$K$1501,0))>0," +Г",""),"-")) | K6: =IF($A6="","",IFERROR(IF(Настройки!$B$4="да",INDEX(Квартиры!$D$2:$D$1501,MATCH($A6*1000+9,Квартиры!$K$2:$K$1501,0))&" / ","")&INDEX(Квартиры!$H$2:$H$1501,MATCH($A6*1000+9,Квартиры!$K$2:$K$1501,0))&" СУ"&IF(INDEX(Квартиры!$I$2:$I$1501,MATCH($A6*1000+9,Квартиры!$K$2:$K$1501,0))>0," +У","")&IF(INDEX(Квартиры!$J$2:$J$1501,MATCH($A6*1000+9,Квартиры!$K$2:$K$1501,0))>0," +Г",""),"-")) | L6: =IF($A6="","",IFERROR(IF(Настройки!$B$4="да",INDEX(Квартиры!$D$2:$D$1501,MATCH($A6*1000+10,Квартиры!$K$2:$K$1501,0))&" / ","")&INDEX(Квартиры!$H$2:$H$1501,MATCH($A6*1000+10,Квартиры!$K$2:$K$1501,0))&" СУ"&IF(INDEX(Квартиры!$I$2:$I$1501,MATCH($A6*1000+10,Квартиры!$K$2:$K$1501,0))>0," +У","")&IF(INDEX(Квартиры!$J$2:$J$1501,MATCH($A6*1000+10,Квартиры!$K$2:$K$1501,0))>0," +Г",""),"-")) | M6: =IF($A6="","",IFERROR(IF(Настройки!$B$4="да",INDEX(Квартиры!$D$2:$D$1501,MATCH($A6*1000+11,Квартиры!$K$2:$K$1501,0))&" / ","")&INDEX(Квартиры!$H$2:$H$1501,MATCH($A6*1000+11,Квартиры!$K$2:$K$1501,0))&" СУ"&IF(INDEX(Квартиры!$I$2:$I$1501,MATCH($A6*1000+11,Квартиры!$K$2:$K$1501,0))>0," +У","")&IF(INDEX(Квартиры!$J$2:$J$1501,MATCH($A6*1000+11,Квартиры!$K$2:$K$1501,0))>0," +Г",""),"-")) | N6: =IF($A6="","",IFERROR(IF(Настройки!$B$4="да",INDEX(Квартиры!$D$2:$D$1501,MATCH($A6*1000+12,Квартиры!$K$2:$K$1501,0))&" / ","")&INDEX(Квартиры!$H$2:$H$1501,MATCH($A6*1000+12,Квартиры!$K$2:$K$1501,0))&" СУ"&IF(INDEX(Квартиры!$I$2:$I$1501,MATCH($A6*1000+12,Квартиры!$K$2:$K$1501,0))>0," +У","")&IF(INDEX(Квартиры!$J$2:$J$1501,MATCH($A6*1000+12,Квартиры!$K$2:$K$1501,0))>0," +Г",""),"-")) | O6: =IF($A6="","",IFERROR(IF(Настройки!$B$4="да",INDEX(Квартиры!$D$2:$D$1501,MATCH($A6*1000+13,Квартиры!$K$2:$K$1501,0))&" / ","")&INDEX(Квартиры!$H$2:$H$1501,MATCH($A6*1000+13,Квартиры!$K$2:$K$1501,0))&" СУ"&IF(INDEX(Квартиры!$I$2:$I$1501,MATCH($A6*1000+13,Квартиры!$K$2:$K$1501,0))>0," +У","")&IF(INDEX(Квартиры!$J$2:$J$1501,MATCH($A6*1000+13,Квартиры!$K$2:$K$1501,0))>0," +Г",""),"-")) | P6: =IF($A6="","",IFERROR(IF(Настройки!$B$4="да",INDEX(Квартиры!$D$2:$D$1501,MATCH($A6*1000+14,Квартиры!$K$2:$K$1501,0))&" / ","")&INDEX(Квартиры!$H$2:$H$1501,MATCH($A6*1000+14,Квартиры!$K$2:$K$1501,0))&" СУ"&IF(INDEX(Квартиры!$I$2:$I$1501,MATCH($A6*1000+14,Квартиры!$K$2:$K$1501,0))>0," +У","")&IF(INDEX(Квартиры!$J$2:$J$1501,MATCH($A6*1000+14,Квартиры!$K$2:$K$1501,0))>0," +Г",""),"-")) | Q6: =IF($A6="","",IFERROR(IF(Настройки!$B$4="да",INDEX(Квартиры!$D$2:$D$1501,MATCH($A6*1000+15,Квартиры!$K$2:$K$1501,0))&" / ","")&INDEX(Квартиры!$H$2:$H$1501,MATCH($A6*1000+15,Квартиры!$K$2:$K$1501,0))&" СУ"&IF(INDEX(Квартиры!$I$2:$I$1501,MATCH($A6*1000+15,Квартиры!$K$2:$K$1501,0))>0," +У","")&IF(INDEX(Квартиры!$J$2:$J$1501,MATCH($A6*1000+15,Квартиры!$K$2:$K$1501,0))>0," +Г",""),"-")) | R6: =IF(A6="","",C6&"|"&D6&"|"&E6&"|"&F6&"|"&G6&"|"&H6&"|"&I6&"|"&J6&"|"&K6&"|"&L6&"|"&M6&"|"&N6&"|"&O6&"|"&P6&"|"&Q6) | S6: =IF(A6="","",IFERROR(LOOKUP(2,1/(B$2:B5=B6),S$2:S5)&", ","")&A6) | U6: =IF(4>MAX(B$3:B$82),"",4) | V6: =IF(U6="","",LOOKUP(2,1/(B$3:B$82=U6),S$3:S$82)) | W6: =IF(U6="","",COUNTIF(B$3:B$82,U6))
A7: =IFERROR(IF(A6="","",SMALL(Квартиры!$B$2:$B$1501,COUNTIF(Квартиры!$B$2:$B$1501,"<="&A6)+1)),"") | B7: =IF(A7="","",IF(COUNTIF(R$2:R6,R7)=0,MAX(B$2:B6)+1,INDEX(B$2:B6,MATCH(R7,R$2:R6,0)))) | C7: =IF($A7="","",IFERROR(IF(Настройки!$B$4="да",INDEX(Квартиры!$D$2:$D$1501,MATCH($A7*1000+1,Квартиры!$K$2:$K$1501,0))&" / ","")&INDEX(Квартиры!$H$2:$H$1501,MATCH($A7*1000+1,Квартиры!$K$2:$K$1501,0))&" СУ"&IF(INDEX(Квартиры!$I$2:$I$1501,MATCH($A7*1000+1,Квартиры!$K$2:$K$1501,0))>0," +У","")&IF(INDEX(Квартиры!$J$2:$J$1501,MATCH($A7*1000+1,Квартиры!$K$2:$K$1501,0))>0," +Г",""),"-")) | D7: =IF($A7="","",IFERROR(IF(Настройки!$B$4="да",INDEX(Квартиры!$D$2:$D$1501,MATCH($A7*1000+2,Квартиры!$K$2:$K$1501,0))&" / ","")&INDEX(Квартиры!$H$2:$H$1501,MATCH($A7*1000+2,Квартиры!$K$2:$K$1501,0))&" СУ"&IF(INDEX(Квартиры!$I$2:$I$1501,MATCH($A7*1000+2,Квартиры!$K$2:$K$1501,0))>0," +У","")&IF(INDEX(Квартиры!$J$2:$J$1501,MATCH($A7*1000+2,Квартиры!$K$2:$K$1501,0))>0," +Г",""),"-")) | E7: =IF($A7="","",IFERROR(IF(Настройки!$B$4="да",INDEX(Квартиры!$D$2:$D$1501,MATCH($A7*1000+3,Квартиры!$K$2:$K$1501,0))&" / ","")&INDEX(Квартиры!$H$2:$H$1501,MATCH($A7*1000+3,Квартиры!$K$2:$K$1501,0))&" СУ"&IF(INDEX(Квартиры!$I$2:$I$1501,MATCH($A7*1000+3,Квартиры!$K$2:$K$1501,0))>0," +У","")&IF(INDEX(Квартиры!$J$2:$J$1501,MATCH($A7*1000+3,Квартиры!$K$2:$K$1501,0))>0," +Г",""),"-")) | F7: =IF($A7="","",IFERROR(IF(Настройки!$B$4="да",INDEX(Квартиры!$D$2:$D$1501,MATCH($A7*1000+4,Квартиры!$K$2:$K$1501,0))&" / ","")&INDEX(Квартиры!$H$2:$H$1501,MATCH($A7*1000+4,Квартиры!$K$2:$K$1501,0))&" СУ"&IF(INDEX(Квартиры!$I$2:$I$1501,MATCH($A7*1000+4,Квартиры!$K$2:$K$1501,0))>0," +У","")&IF(INDEX(Квартиры!$J$2:$J$1501,MATCH($A7*1000+4,Квартиры!$K$2:$K$1501,0))>0," +Г",""),"-")) | G7: =IF($A7="","",IFERROR(IF(Настройки!$B$4="да",INDEX(Квартиры!$D$2:$D$1501,MATCH($A7*1000+5,Квартиры!$K$2:$K$1501,0))&" / ","")&INDEX(Квартиры!$H$2:$H$1501,MATCH($A7*1000+5,Квартиры!$K$2:$K$1501,0))&" СУ"&IF(INDEX(Квартиры!$I$2:$I$1501,MATCH($A7*1000+5,Квартиры!$K$2:$K$1501,0))>0," +У","")&IF(INDEX(Квартиры!$J$2:$J$1501,MATCH($A7*1000+5,Квартиры!$K$2:$K$1501,0))>0," +Г",""),"-")) | H7: =IF($A7="","",IFERROR(IF(Настройки!$B$4="да",INDEX(Квартиры!$D$2:$D$1501,MATCH($A7*1000+6,Квартиры!$K$2:$K$1501,0))&" / ","")&INDEX(Квартиры!$H$2:$H$1501,MATCH($A7*1000+6,Квартиры!$K$2:$K$1501,0))&" СУ"&IF(INDEX(Квартиры!$I$2:$I$1501,MATCH($A7*1000+6,Квартиры!$K$2:$K$1501,0))>0," +У","")&IF(INDEX(Квартиры!$J$2:$J$1501,MATCH($A7*1000+6,Квартиры!$K$2:$K$1501,0))>0," +Г",""),"-")) | I7: =IF($A7="","",IFERROR(IF(Настройки!$B$4="да",INDEX(Квартиры!$D$2:$D$1501,MATCH($A7*1000+7,Квартиры!$K$2:$K$1501,0))&" / ","")&INDEX(Квартиры!$H$2:$H$1501,MATCH($A7*1000+7,Квартиры!$K$2:$K$1501,0))&" СУ"&IF(INDEX(Квартиры!$I$2:$I$1501,MATCH($A7*1000+7,Квартиры!$K$2:$K$1501,0))>0," +У","")&IF(INDEX(Квартиры!$J$2:$J$1501,MATCH($A7*1000+7,Квартиры!$K$2:$K$1501,0))>0," +Г",""),"-")) | J7: =IF($A7="","",IFERROR(IF(Настройки!$B$4="да",INDEX(Квартиры!$D$2:$D$1501,MATCH($A7*1000+8,Квартиры!$K$2:$K$1501,0))&" / ","")&INDEX(Квартиры!$H$2:$H$1501,MATCH($A7*1000+8,Квартиры!$K$2:$K$1501,0))&" СУ"&IF(INDEX(Квартиры!$I$2:$I$1501,MATCH($A7*1000+8,Квартиры!$K$2:$K$1501,0))>0," +У","")&IF(INDEX(Квартиры!$J$2:$J$1501,MATCH($A7*1000+8,Квартиры!$K$2:$K$1501,0))>0," +Г",""),"-")) | K7: =IF($A7="","",IFERROR(IF(Настройки!$B$4="да",INDEX(Квартиры!$D$2:$D$1501,MATCH($A7*1000+9,Квартиры!$K$2:$K$1501,0))&" / ","")&INDEX(Квартиры!$H$2:$H$1501,MATCH($A7*1000+9,Квартиры!$K$2:$K$1501,0))&" СУ"&IF(INDEX(Квартиры!$I$2:$I$1501,MATCH($A7*1000+9,Квартиры!$K$2:$K$1501,0))>0," +У","")&IF(INDEX(Квартиры!$J$2:$J$1501,MATCH($A7*1000+9,Квартиры!$K$2:$K$1501,0))>0," +Г",""),"-")) | L7: =IF($A7="","",IFERROR(IF(Настройки!$B$4="да",INDEX(Квартиры!$D$2:$D$1501,MATCH($A7*1000+10,Квартиры!$K$2:$K$1501,0))&" / ","")&INDEX(Квартиры!$H$2:$H$1501,MATCH($A7*1000+10,Квартиры!$K$2:$K$1501,0))&" СУ"&IF(INDEX(Квартиры!$I$2:$I$1501,MATCH($A7*1000+10,Квартиры!$K$2:$K$1501,0))>0," +У","")&IF(INDEX(Квартиры!$J$2:$J$1501,MATCH($A7*1000+10,Квартиры!$K$2:$K$1501,0))>0," +Г",""),"-")) | M7: =IF($A7="","",IFERROR(IF(Настройки!$B$4="да",INDEX(Квартиры!$D$2:$D$1501,MATCH($A7*1000+11,Квартиры!$K$2:$K$1501,0))&" / ","")&INDEX(Квартиры!$H$2:$H$1501,MATCH($A7*1000+11,Квартиры!$K$2:$K$1501,0))&" СУ"&IF(INDEX(Квартиры!$I$2:$I$1501,MATCH($A7*1000+11,Квартиры!$K$2:$K$1501,0))>0," +У","")&IF(INDEX(Квартиры!$J$2:$J$1501,MATCH($A7*1000+11,Квартиры!$K$2:$K$1501,0))>0," +Г",""),"-")) | N7: =IF($A7="","",IFERROR(IF(Настройки!$B$4="да",INDEX(Квартиры!$D$2:$D$1501,MATCH($A7*1000+12,Квартиры!$K$2:$K$1501,0))&" / ","")&INDEX(Квартиры!$H$2:$H$1501,MATCH($A7*1000+12,Квартиры!$K$2:$K$1501,0))&" СУ"&IF(INDEX(Квартиры!$I$2:$I$1501,MATCH($A7*1000+12,Квартиры!$K$2:$K$1501,0))>0," +У","")&IF(INDEX(Квартиры!$J$2:$J$1501,MATCH($A7*1000+12,Квартиры!$K$2:$K$1501,0))>0," +Г",""),"-")) | O7: =IF($A7="","",IFERROR(IF(Настройки!$B$4="да",INDEX(Квартиры!$D$2:$D$1501,MATCH($A7*1000+13,Квартиры!$K$2:$K$1501,0))&" / ","")&INDEX(Квартиры!$H$2:$H$1501,MATCH($A7*1000+13,Квартиры!$K$2:$K$1501,0))&" СУ"&IF(INDEX(Квартиры!$I$2:$I$1501,MATCH($A7*1000+13,Квартиры!$K$2:$K$1501,0))>0," +У","")&IF(INDEX(Квартиры!$J$2:$J$1501,MATCH($A7*1000+13,Квартиры!$K$2:$K$1501,0))>0," +Г",""),"-")) | P7: =IF($A7="","",IFERROR(IF(Настройки!$B$4="да",INDEX(Квартиры!$D$2:$D$1501,MATCH($A7*1000+14,Квартиры!$K$2:$K$1501,0))&" / ","")&INDEX(Квартиры!$H$2:$H$1501,MATCH($A7*1000+14,Квартиры!$K$2:$K$1501,0))&" СУ"&IF(INDEX(Квартиры!$I$2:$I$1501,MATCH($A7*1000+14,Квартиры!$K$2:$K$1501,0))>0," +У","")&IF(INDEX(Квартиры!$J$2:$J$1501,MATCH($A7*1000+14,Квартиры!$K$2:$K$1501,0))>0," +Г",""),"-")) | Q7: =IF($A7="","",IFERROR(IF(Настройки!$B$4="да",INDEX(Квартиры!$D$2:$D$1501,MATCH($A7*1000+15,Квартиры!$K$2:$K$1501,0))&" / ","")&INDEX(Квартиры!$H$2:$H$1501,MATCH($A7*1000+15,Квартиры!$K$2:$K$1501,0))&" СУ"&IF(INDEX(Квартиры!$I$2:$I$1501,MATCH($A7*1000+15,Квартиры!$K$2:$K$1501,0))>0," +У","")&IF(INDEX(Квартиры!$J$2:$J$1501,MATCH($A7*1000+15,Квартиры!$K$2:$K$1501,0))>0," +Г",""),"-")) | R7: =IF(A7="","",C7&"|"&D7&"|"&E7&"|"&F7&"|"&G7&"|"&H7&"|"&I7&"|"&J7&"|"&K7&"|"&L7&"|"&M7&"|"&N7&"|"&O7&"|"&P7&"|"&Q7) | S7: =IF(A7="","",IFERROR(LOOKUP(2,1/(B$2:B6=B7),S$2:S6)&", ","")&A7) | U7: =IF(5>MAX(B$3:B$82),"",5) | V7: =IF(U7="","",LOOKUP(2,1/(B$3:B$82=U7),S$3:S$82)) | W7: =IF(U7="","",COUNTIF(B$3:B$82,U7))
A8: =IFERROR(IF(A7="","",SMALL(Квартиры!$B$2:$B$1501,COUNTIF(Квартиры!$B$2:$B$1501,"<="&A7)+1)),"") | B8: =IF(A8="","",IF(COUNTIF(R$2:R7,R8)=0,MAX(B$2:B7)+1,INDEX(B$2:B7,MATCH(R8,R$2:R7,0)))) | C8: =IF($A8="","",IFERROR(IF(Настройки!$B$4="да",INDEX(Квартиры!$D$2:$D$1501,MATCH($A8*1000+1,Квартиры!$K$2:$K$1501,0))&" / ","")&INDEX(Квартиры!$H$2:$H$1501,MATCH($A8*1000+1,Квартиры!$K$2:$K$1501,0))&" СУ"&IF(INDEX(Квартиры!$I$2:$I$1501,MATCH($A8*1000+1,Квартиры!$K$2:$K$1501,0))>0," +У","")&IF(INDEX(Квартиры!$J$2:$J$1501,MATCH($A8*1000+1,Квартиры!$K$2:$K$1501,0))>0," +Г",""),"-")) | D8: =IF($A8="","",IFERROR(IF(Настройки!$B$4="да",INDEX(Квартиры!$D$2:$D$1501,MATCH($A8*1000+2,Квартиры!$K$2:$K$1501,0))&" / ","")&INDEX(Квартиры!$H$2:$H$1501,MATCH($A8*1000+2,Квартиры!$K$2:$K$1501,0))&" СУ"&IF(INDEX(Квартиры!$I$2:$I$1501,MATCH($A8*1000+2,Квартиры!$K$2:$K$1501,0))>0," +У","")&IF(INDEX(Квартиры!$J$2:$J$1501,MATCH($A8*1000+2,Квартиры!$K$2:$K$1501,0))>0," +Г",""),"-")) | E8: =IF($A8="","",IFERROR(IF(Настройки!$B$4="да",INDEX(Квартиры!$D$2:$D$1501,MATCH($A8*1000+3,Квартиры!$K$2:$K$1501,0))&" / ","")&INDEX(Квартиры!$H$2:$H$1501,MATCH($A8*1000+3,Квартиры!$K$2:$K$1501,0))&" СУ"&IF(INDEX(Квартиры!$I$2:$I$1501,MATCH($A8*1000+3,Квартиры!$K$2:$K$1501,0))>0," +У","")&IF(INDEX(Квартиры!$J$2:$J$1501,MATCH($A8*1000+3,Квартиры!$K$2:$K$1501,0))>0," +Г",""),"-")) | F8: =IF($A8="","",IFERROR(IF(Настройки!$B$4="да",INDEX(Квартиры!$D$2:$D$1501,MATCH($A8*1000+4,Квартиры!$K$2:$K$1501,0))&" / ","")&INDEX(Квартиры!$H$2:$H$1501,MATCH($A8*1000+4,Квартиры!$K$2:$K$1501,0))&" СУ"&IF(INDEX(Квартиры!$I$2:$I$1501,MATCH($A8*1000+4,Квартиры!$K$2:$K$1501,0))>0," +У","")&IF(INDEX(Квартиры!$J$2:$J$1501,MATCH($A8*1000+4,Квартиры!$K$2:$K$1501,0))>0," +Г",""),"-")) | G8: =IF($A8="","",IFERROR(IF(Настройки!$B$4="да",INDEX(Квартиры!$D$2:$D$1501,MATCH($A8*1000+5,Квартиры!$K$2:$K$1501,0))&" / ","")&INDEX(Квартиры!$H$2:$H$1501,MATCH($A8*1000+5,Квартиры!$K$2:$K$1501,0))&" СУ"&IF(INDEX(Квартиры!$I$2:$I$1501,MATCH($A8*1000+5,Квартиры!$K$2:$K$1501,0))>0," +У","")&IF(INDEX(Квартиры!$J$2:$J$1501,MATCH($A8*1000+5,Квартиры!$K$2:$K$1501,0))>0," +Г",""),"-")) | H8: =IF($A8="","",IFERROR(IF(Настройки!$B$4="да",INDEX(Квартиры!$D$2:$D$1501,MATCH($A8*1000+6,Квартиры!$K$2:$K$1501,0))&" / ","")&INDEX(Квартиры!$H$2:$H$1501,MATCH($A8*1000+6,Квартиры!$K$2:$K$1501,0))&" СУ"&IF(INDEX(Квартиры!$I$2:$I$1501,MATCH($A8*1000+6,Квартиры!$K$2:$K$1501,0))>0," +У","")&IF(INDEX(Квартиры!$J$2:$J$1501,MATCH($A8*1000+6,Квартиры!$K$2:$K$1501,0))>0," +Г",""),"-")) | I8: =IF($A8="","",IFERROR(IF(Настройки!$B$4="да",INDEX(Квартиры!$D$2:$D$1501,MATCH($A8*1000+7,Квартиры!$K$2:$K$1501,0))&" / ","")&INDEX(Квартиры!$H$2:$H$1501,MATCH($A8*1000+7,Квартиры!$K$2:$K$1501,0))&" СУ"&IF(INDEX(Квартиры!$I$2:$I$1501,MATCH($A8*1000+7,Квартиры!$K$2:$K$1501,0))>0," +У","")&IF(INDEX(Квартиры!$J$2:$J$1501,MATCH($A8*1000+7,Квартиры!$K$2:$K$1501,0))>0," +Г",""),"-")) | J8: =IF($A8="","",IFERROR(IF(Настройки!$B$4="да",INDEX(Квартиры!$D$2:$D$1501,MATCH($A8*1000+8,Квартиры!$K$2:$K$1501,0))&" / ","")&INDEX(Квартиры!$H$2:$H$1501,MATCH($A8*1000+8,Квартиры!$K$2:$K$1501,0))&" СУ"&IF(INDEX(Квартиры!$I$2:$I$1501,MATCH($A8*1000+8,Квартиры!$K$2:$K$1501,0))>0," +У","")&IF(INDEX(Квартиры!$J$2:$J$1501,MATCH($A8*1000+8,Квартиры!$K$2:$K$1501,0))>0," +Г",""),"-")) | K8: =IF($A8="","",IFERROR(IF(Настройки!$B$4="да",INDEX(Квартиры!$D$2:$D$1501,MATCH($A8*1000+9,Квартиры!$K$2:$K$1501,0))&" / ","")&INDEX(Квартиры!$H$2:$H$1501,MATCH($A8*1000+9,Квартиры!$K$2:$K$1501,0))&" СУ"&IF(INDEX(Квартиры!$I$2:$I$1501,MATCH($A8*1000+9,Квартиры!$K$2:$K$1501,0))>0," +У","")&IF(INDEX(Квартиры!$J$2:$J$1501,MATCH($A8*1000+9,Квартиры!$K$2:$K$1501,0))>0," +Г",""),"-")) | L8: =IF($A8="","",IFERROR(IF(Настройки!$B$4="да",INDEX(Квартиры!$D$2:$D$1501,MATCH($A8*1000+10,Квартиры!$K$2:$K$1501,0))&" / ","")&INDEX(Квартиры!$H$2:$H$1501,MATCH($A8*1000+10,Квартиры!$K$2:$K$1501,0))&" СУ"&IF(INDEX(Квартиры!$I$2:$I$1501,MATCH($A8*1000+10,Квартиры!$K$2:$K$1501,0))>0," +У","")&IF(INDEX(Квартиры!$J$2:$J$1501,MATCH($A8*1000+10,Квартиры!$K$2:$K$1501,0))>0," +Г",""),"-")) | M8: =IF($A8="","",IFERROR(IF(Настройки!$B$4="да",INDEX(Квартиры!$D$2:$D$1501,MATCH($A8*1000+11,Квартиры!$K$2:$K$1501,0))&" / ","")&INDEX(Квартиры!$H$2:$H$1501,MATCH($A8*1000+11,Квартиры!$K$2:$K$1501,0))&" СУ"&IF(INDEX(Квартиры!$I$2:$I$1501,MATCH($A8*1000+11,Квартиры!$K$2:$K$1501,0))>0," +У","")&IF(INDEX(Квартиры!$J$2:$J$1501,MATCH($A8*1000+11,Квартиры!$K$2:$K$1501,0))>0," +Г",""),"-")) | N8: =IF($A8="","",IFERROR(IF(Настройки!$B$4="да",INDEX(Квартиры!$D$2:$D$1501,MATCH($A8*1000+12,Квартиры!$K$2:$K$1501,0))&" / ","")&INDEX(Квартиры!$H$2:$H$1501,MATCH($A8*1000+12,Квартиры!$K$2:$K$1501,0))&" СУ"&IF(INDEX(Квартиры!$I$2:$I$1501,MATCH($A8*1000+12,Квартиры!$K$2:$K$1501,0))>0," +У","")&IF(INDEX(Квартиры!$J$2:$J$1501,MATCH($A8*1000+12,Квартиры!$K$2:$K$1501,0))>0," +Г",""),"-")) | O8: =IF($A8="","",IFERROR(IF(Настройки!$B$4="да",INDEX(Квартиры!$D$2:$D$1501,MATCH($A8*1000+13,Квартиры!$K$2:$K$1501,0))&" / ","")&INDEX(Квартиры!$H$2:$H$1501,MATCH($A8*1000+13,Квартиры!$K$2:$K$1501,0))&" СУ"&IF(INDEX(Квартиры!$I$2:$I$1501,MATCH($A8*1000+13,Квартиры!$K$2:$K$1501,0))>0," +У","")&IF(INDEX(Квартиры!$J$2:$J$1501,MATCH($A8*1000+13,Квартиры!$K$2:$K$1501,0))>0," +Г",""),"-")) | P8: =IF($A8="","",IFERROR(IF(Настройки!$B$4="да",INDEX(Квартиры!$D$2:$D$1501,MATCH($A8*1000+14,Квартиры!$K$2:$K$1501,0))&" / ","")&INDEX(Квартиры!$H$2:$H$1501,MATCH($A8*1000+14,Квартиры!$K$2:$K$1501,0))&" СУ"&IF(INDEX(Квартиры!$I$2:$I$1501,MATCH($A8*1000+14,Квартиры!$K$2:$K$1501,0))>0," +У","")&IF(INDEX(Квартиры!$J$2:$J$1501,MATCH($A8*1000+14,Квартиры!$K$2:$K$1501,0))>0," +Г",""),"-")) | Q8: =IF($A8="","",IFERROR(IF(Настройки!$B$4="да",INDEX(Квартиры!$D$2:$D$1501,MATCH($A8*1000+15,Квартиры!$K$2:$K$1501,0))&" / ","")&INDEX(Квартиры!$H$2:$H$1501,MATCH($A8*1000+15,Квартиры!$K$2:$K$1501,0))&" СУ"&IF(INDEX(Квартиры!$I$2:$I$1501,MATCH($A8*1000+15,Квартиры!$K$2:$K$1501,0))>0," +У","")&IF(INDEX(Квартиры!$J$2:$J$1501,MATCH($A8*1000+15,Квартиры!$K$2:$K$1501,0))>0," +Г",""),"-")) | R8: =IF(A8="","",C8&"|"&D8&"|"&E8&"|"&F8&"|"&G8&"|"&H8&"|"&I8&"|"&J8&"|"&K8&"|"&L8&"|"&M8&"|"&N8&"|"&O8&"|"&P8&"|"&Q8) | S8: =IF(A8="","",IFERROR(LOOKUP(2,1/(B$2:B7=B8),S$2:S7)&", ","")&A8) | U8: =IF(6>MAX(B$3:B$82),"",6) | V8: =IF(U8="","",LOOKUP(2,1/(B$3:B$82=U8),S$3:S$82)) | W8: =IF(U8="","",COUNTIF(B$3:B$82,U8))
A9: =IFERROR(IF(A8="","",SMALL(Квартиры!$B$2:$B$1501,COUNTIF(Квартиры!$B$2:$B$1501,"<="&A8)+1)),"") | B9: =IF(A9="","",IF(COUNTIF(R$2:R8,R9)=0,MAX(B$2:B8)+1,INDEX(B$2:B8,MATCH(R9,R$2:R8,0)))) | C9: =IF($A9="","",IFERROR(IF(Настройки!$B$4="да",INDEX(Квартиры!$D$2:$D$1501,MATCH($A9*1000+1,Квартиры!$K$2:$K$1501,0))&" / ","")&INDEX(Квартиры!$H$2:$H$1501,MATCH($A9*1000+1,Квартиры!$K$2:$K$1501,0))&" СУ"&IF(INDEX(Квартиры!$I$2:$I$1501,MATCH($A9*1000+1,Квартиры!$K$2:$K$1501,0))>0," +У","")&IF(INDEX(Квартиры!$J$2:$J$1501,MATCH($A9*1000+1,Квартиры!$K$2:$K$1501,0))>0," +Г",""),"-")) | D9: =IF($A9="","",IFERROR(IF(Настройки!$B$4="да",INDEX(Квартиры!$D$2:$D$1501,MATCH($A9*1000+2,Квартиры!$K$2:$K$1501,0))&" / ","")&INDEX(Квартиры!$H$2:$H$1501,MATCH($A9*1000+2,Квартиры!$K$2:$K$1501,0))&" СУ"&IF(INDEX(Квартиры!$I$2:$I$1501,MATCH($A9*1000+2,Квартиры!$K$2:$K$1501,0))>0," +У","")&IF(INDEX(Квартиры!$J$2:$J$1501,MATCH($A9*1000+2,Квартиры!$K$2:$K$1501,0))>0," +Г",""),"-")) | E9: =IF($A9="","",IFERROR(IF(Настройки!$B$4="да",INDEX(Квартиры!$D$2:$D$1501,MATCH($A9*1000+3,Квартиры!$K$2:$K$1501,0))&" / ","")&INDEX(Квартиры!$H$2:$H$1501,MATCH($A9*1000+3,Квартиры!$K$2:$K$1501,0))&" СУ"&IF(INDEX(Квартиры!$I$2:$I$1501,MATCH($A9*1000+3,Квартиры!$K$2:$K$1501,0))>0," +У","")&IF(INDEX(Квартиры!$J$2:$J$1501,MATCH($A9*1000+3,Квартиры!$K$2:$K$1501,0))>0," +Г",""),"-")) | F9: =IF($A9="","",IFERROR(IF(Настройки!$B$4="да",INDEX(Квартиры!$D$2:$D$1501,MATCH($A9*1000+4,Квартиры!$K$2:$K$1501,0))&" / ","")&INDEX(Квартиры!$H$2:$H$1501,MATCH($A9*1000+4,Квартиры!$K$2:$K$1501,0))&" СУ"&IF(INDEX(Квартиры!$I$2:$I$1501,MATCH($A9*1000+4,Квартиры!$K$2:$K$1501,0))>0," +У","")&IF(INDEX(Квартиры!$J$2:$J$1501,MATCH($A9*1000+4,Квартиры!$K$2:$K$1501,0))>0," +Г",""),"-")) | G9: =IF($A9="","",IFERROR(IF(Настройки!$B$4="да",INDEX(Квартиры!$D$2:$D$1501,MATCH($A9*1000+5,Квартиры!$K$2:$K$1501,0))&" / ","")&INDEX(Квартиры!$H$2:$H$1501,MATCH($A9*1000+5,Квартиры!$K$2:$K$1501,0))&" СУ"&IF(INDEX(Квартиры!$I$2:$I$1501,MATCH($A9*1000+5,Квартиры!$K$2:$K$1501,0))>0," +У","")&IF(INDEX(Квартиры!$J$2:$J$1501,MATCH($A9*1000+5,Квартиры!$K$2:$K$1501,0))>0," +Г",""),"-")) | H9: =IF($A9="","",IFERROR(IF(Настройки!$B$4="да",INDEX(Квартиры!$D$2:$D$1501,MATCH($A9*1000+6,Квартиры!$K$2:$K$1501,0))&" / ","")&INDEX(Квартиры!$H$2:$H$1501,MATCH($A9*1000+6,Квартиры!$K$2:$K$1501,0))&" СУ"&IF(INDEX(Квартиры!$I$2:$I$1501,MATCH($A9*1000+6,Квартиры!$K$2:$K$1501,0))>0," +У","")&IF(INDEX(Квартиры!$J$2:$J$1501,MATCH($A9*1000+6,Квартиры!$K$2:$K$1501,0))>0," +Г",""),"-")) | I9: =IF($A9="","",IFERROR(IF(Настройки!$B$4="да",INDEX(Квартиры!$D$2:$D$1501,MATCH($A9*1000+7,Квартиры!$K$2:$K$1501,0))&" / ","")&INDEX(Квартиры!$H$2:$H$1501,MATCH($A9*1000+7,Квартиры!$K$2:$K$1501,0))&" СУ"&IF(INDEX(Квартиры!$I$2:$I$1501,MATCH($A9*1000+7,Квартиры!$K$2:$K$1501,0))>0," +У","")&IF(INDEX(Квартиры!$J$2:$J$1501,MATCH($A9*1000+7,Квартиры!$K$2:$K$1501,0))>0," +Г",""),"-")) | J9: =IF($A9="","",IFERROR(IF(Настройки!$B$4="да",INDEX(Квартиры!$D$2:$D$1501,MATCH($A9*1000+8,Квартиры!$K$2:$K$1501,0))&" / ","")&INDEX(Квартиры!$H$2:$H$1501,MATCH($A9*1000+8,Квартиры!$K$2:$K$1501,0))&" СУ"&IF(INDEX(Квартиры!$I$2:$I$1501,MATCH($A9*1000+8,Квартиры!$K$2:$K$1501,0))>0," +У","")&IF(INDEX(Квартиры!$J$2:$J$1501,MATCH($A9*1000+8,Квартиры!$K$2:$K$1501,0))>0," +Г",""),"-")) | K9: =IF($A9="","",IFERROR(IF(Настройки!$B$4="да",INDEX(Квартиры!$D$2:$D$1501,MATCH($A9*1000+9,Квартиры!$K$2:$K$1501,0))&" / ","")&INDEX(Квартиры!$H$2:$H$1501,MATCH($A9*1000+9,Квартиры!$K$2:$K$1501,0))&" СУ"&IF(INDEX(Квартиры!$I$2:$I$1501,MATCH($A9*1000+9,Квартиры!$K$2:$K$1501,0))>0," +У","")&IF(INDEX(Квартиры!$J$2:$J$1501,MATCH($A9*1000+9,Квартиры!$K$2:$K$1501,0))>0," +Г",""),"-")) | L9: =IF($A9="","",IFERROR(IF(Настройки!$B$4="да",INDEX(Квартиры!$D$2:$D$1501,MATCH($A9*1000+10,Квартиры!$K$2:$K$1501,0))&" / ","")&INDEX(Квартиры!$H$2:$H$1501,MATCH($A9*1000+10,Квартиры!$K$2:$K$1501,0))&" СУ"&IF(INDEX(Квартиры!$I$2:$I$1501,MATCH($A9*1000+10,Квартиры!$K$2:$K$1501,0))>0," +У","")&IF(INDEX(Квартиры!$J$2:$J$1501,MATCH($A9*1000+10,Квартиры!$K$2:$K$1501,0))>0," +Г",""),"-")) | M9: =IF($A9="","",IFERROR(IF(Настройки!$B$4="да",INDEX(Квартиры!$D$2:$D$1501,MATCH($A9*1000+11,Квартиры!$K$2:$K$1501,0))&" / ","")&INDEX(Квартиры!$H$2:$H$1501,MATCH($A9*1000+11,Квартиры!$K$2:$K$1501,0))&" СУ"&IF(INDEX(Квартиры!$I$2:$I$1501,MATCH($A9*1000+11,Квартиры!$K$2:$K$1501,0))>0," +У","")&IF(INDEX(Квартиры!$J$2:$J$1501,MATCH($A9*1000+11,Квартиры!$K$2:$K$1501,0))>0," +Г",""),"-")) | N9: =IF($A9="","",IFERROR(IF(Настройки!$B$4="да",INDEX(Квартиры!$D$2:$D$1501,MATCH($A9*1000+12,Квартиры!$K$2:$K$1501,0))&" / ","")&INDEX(Квартиры!$H$2:$H$1501,MATCH($A9*1000+12,Квартиры!$K$2:$K$1501,0))&" СУ"&IF(INDEX(Квартиры!$I$2:$I$1501,MATCH($A9*1000+12,Квартиры!$K$2:$K$1501,0))>0," +У","")&IF(INDEX(Квартиры!$J$2:$J$1501,MATCH($A9*1000+12,Квартиры!$K$2:$K$1501,0))>0," +Г",""),"-")) | O9: =IF($A9="","",IFERROR(IF(Настройки!$B$4="да",INDEX(Квартиры!$D$2:$D$1501,MATCH($A9*1000+13,Квартиры!$K$2:$K$1501,0))&" / ","")&INDEX(Квартиры!$H$2:$H$1501,MATCH($A9*1000+13,Квартиры!$K$2:$K$1501,0))&" СУ"&IF(INDEX(Квартиры!$I$2:$I$1501,MATCH($A9*1000+13,Квартиры!$K$2:$K$1501,0))>0," +У","")&IF(INDEX(Квартиры!$J$2:$J$1501,MATCH($A9*1000+13,Квартиры!$K$2:$K$1501,0))>0," +Г",""),"-")) | P9: =IF($A9="","",IFERROR(IF(Настройки!$B$4="да",INDEX(Квартиры!$D$2:$D$1501,MATCH($A9*1000+14,Квартиры!$K$2:$K$1501,0))&" / ","")&INDEX(Квартиры!$H$2:$H$1501,MATCH($A9*1000+14,Квартиры!$K$2:$K$1501,0))&" СУ"&IF(INDEX(Квартиры!$I$2:$I$1501,MATCH($A9*1000+14,Квартиры!$K$2:$K$1501,0))>0," +У","")&IF(INDEX(Квартиры!$J$2:$J$1501,MATCH($A9*1000+14,Квартиры!$K$2:$K$1501,0))>0," +Г",""),"-")) | Q9: =IF($A9="","",IFERROR(IF(Настройки!$B$4="да",INDEX(Квартиры!$D$2:$D$1501,MATCH($A9*1000+15,Квартиры!$K$2:$K$1501,0))&" / ","")&INDEX(Квартиры!$H$2:$H$1501,MATCH($A9*1000+15,Квартиры!$K$2:$K$1501,0))&" СУ"&IF(INDEX(Квартиры!$I$2:$I$1501,MATCH($A9*1000+15,Квартиры!$K$2:$K$1501,0))>0," +У","")&IF(INDEX(Квартиры!$J$2:$J$1501,MATCH($A9*1000+15,Квартиры!$K$2:$K$1501,0))>0," +Г",""),"-")) | R9: =IF(A9="","",C9&"|"&D9&"|"&E9&"|"&F9&"|"&G9&"|"&H9&"|"&I9&"|"&J9&"|"&K9&"|"&L9&"|"&M9&"|"&N9&"|"&O9&"|"&P9&"|"&Q9) | S9: =IF(A9="","",IFERROR(LOOKUP(2,1/(B$2:B8=B9),S$2:S8)&", ","")&A9) | U9: =IF(7>MAX(B$3:B$82),"",7) | V9: =IF(U9="","",LOOKUP(2,1/(B$3:B$82=U9),S$3:S$82)) | W9: =IF(U9="","",COUNTIF(B$3:B$82,U9))
A10: =IFERROR(IF(A9="","",SMALL(Квартиры!$B$2:$B$1501,COUNTIF(Квартиры!$B$2:$B$1501,"<="&A9)+1)),"") | B10: =IF(A10="","",IF(COUNTIF(R$2:R9,R10)=0,MAX(B$2:B9)+1,INDEX(B$2:B9,MATCH(R10,R$2:R9,0)))) | C10: =IF($A10="","",IFERROR(IF(Настройки!$B$4="да",INDEX(Квартиры!$D$2:$D$1501,MATCH($A10*1000+1,Квартиры!$K$2:$K$1501,0))&" / ","")&INDEX(Квартиры!$H$2:$H$1501,MATCH($A10*1000+1,Квартиры!$K$2:$K$1501,0))&" СУ"&IF(INDEX(Квартиры!$I$2:$I$1501,MATCH($A10*1000+1,Квартиры!$K$2:$K$1501,0))>0," +У","")&IF(INDEX(Квартиры!$J$2:$J$1501,MATCH($A10*1000+1,Квартиры!$K$2:$K$1501,0))>0," +Г",""),"-")) | D10: =IF($A10="","",IFERROR(IF(Настройки!$B$4="да",INDEX(Квартиры!$D$2:$D$1501,MATCH($A10*1000+2,Квартиры!$K$2:$K$1501,0))&" / ","")&INDEX(Квартиры!$H$2:$H$1501,MATCH($A10*1000+2,Квартиры!$K$2:$K$1501,0))&" СУ"&IF(INDEX(Квартиры!$I$2:$I$1501,MATCH($A10*1000+2,Квартиры!$K$2:$K$1501,0))>0," +У","")&IF(INDEX(Квартиры!$J$2:$J$1501,MATCH($A10*1000+2,Квартиры!$K$2:$K$1501,0))>0," +Г",""),"-")) | E10: =IF($A10="","",IFERROR(IF(Настройки!$B$4="да",INDEX(Квартиры!$D$2:$D$1501,MATCH($A10*1000+3,Квартиры!$K$2:$K$1501,0))&" / ","")&INDEX(Квартиры!$H$2:$H$1501,MATCH($A10*1000+3,Квартиры!$K$2:$K$1501,0))&" СУ"&IF(INDEX(Квартиры!$I$2:$I$1501,MATCH($A10*1000+3,Квартиры!$K$2:$K$1501,0))>0," +У","")&IF(INDEX(Квартиры!$J$2:$J$1501,MATCH($A10*1000+3,Квартиры!$K$2:$K$1501,0))>0," +Г",""),"-")) | F10: =IF($A10="","",IFERROR(IF(Настройки!$B$4="да",INDEX(Квартиры!$D$2:$D$1501,MATCH($A10*1000+4,Квартиры!$K$2:$K$1501,0))&" / ","")&INDEX(Квартиры!$H$2:$H$1501,MATCH($A10*1000+4,Квартиры!$K$2:$K$1501,0))&" СУ"&IF(INDEX(Квартиры!$I$2:$I$1501,MATCH($A10*1000+4,Квартиры!$K$2:$K$1501,0))>0," +У","")&IF(INDEX(Квартиры!$J$2:$J$1501,MATCH($A10*1000+4,Квартиры!$K$2:$K$1501,0))>0," +Г",""),"-")) | G10: =IF($A10="","",IFERROR(IF(Настройки!$B$4="да",INDEX(Квартиры!$D$2:$D$1501,MATCH($A10*1000+5,Квартиры!$K$2:$K$1501,0))&" / ","")&INDEX(Квартиры!$H$2:$H$1501,MATCH($A10*1000+5,Квартиры!$K$2:$K$1501,0))&" СУ"&IF(INDEX(Квартиры!$I$2:$I$1501,MATCH($A10*1000+5,Квартиры!$K$2:$K$1501,0))>0," +У","")&IF(INDEX(Квартиры!$J$2:$J$1501,MATCH($A10*1000+5,Квартиры!$K$2:$K$1501,0))>0," +Г",""),"-")) | H10: =IF($A10="","",IFERROR(IF(Настройки!$B$4="да",INDEX(Квартиры!$D$2:$D$1501,MATCH($A10*1000+6,Квартиры!$K$2:$K$1501,0))&" / ","")&INDEX(Квартиры!$H$2:$H$1501,MATCH($A10*1000+6,Квартиры!$K$2:$K$1501,0))&" СУ"&IF(INDEX(Квартиры!$I$2:$I$1501,MATCH($A10*1000+6,Квартиры!$K$2:$K$1501,0))>0," +У","")&IF(INDEX(Квартиры!$J$2:$J$1501,MATCH($A10*1000+6,Квартиры!$K$2:$K$1501,0))>0," +Г",""),"-")) | I10: =IF($A10="","",IFERROR(IF(Настройки!$B$4="да",INDEX(Квартиры!$D$2:$D$1501,MATCH($A10*1000+7,Квартиры!$K$2:$K$1501,0))&" / ","")&INDEX(Квартиры!$H$2:$H$1501,MATCH($A10*1000+7,Квартиры!$K$2:$K$1501,0))&" СУ"&IF(INDEX(Квартиры!$I$2:$I$1501,MATCH($A10*1000+7,Квартиры!$K$2:$K$1501,0))>0," +У","")&IF(INDEX(Квартиры!$J$2:$J$1501,MATCH($A10*1000+7,Квартиры!$K$2:$K$1501,0))>0," +Г",""),"-")) | J10: =IF($A10="","",IFERROR(IF(Настройки!$B$4="да",INDEX(Квартиры!$D$2:$D$1501,MATCH($A10*1000+8,Квартиры!$K$2:$K$1501,0))&" / ","")&INDEX(Квартиры!$H$2:$H$1501,MATCH($A10*1000+8,Квартиры!$K$2:$K$1501,0))&" СУ"&IF(INDEX(Квартиры!$I$2:$I$1501,MATCH($A10*1000+8,Квартиры!$K$2:$K$1501,0))>0," +У","")&IF(INDEX(Квартиры!$J$2:$J$1501,MATCH($A10*1000+8,Квартиры!$K$2:$K$1501,0))>0," +Г",""),"-")) | K10: =IF($A10="","",IFERROR(IF(Настройки!$B$4="да",INDEX(Квартиры!$D$2:$D$1501,MATCH($A10*1000+9,Квартиры!$K$2:$K$1501,0))&" / ","")&INDEX(Квартиры!$H$2:$H$1501,MATCH($A10*1000+9,Квартиры!$K$2:$K$1501,0))&" СУ"&IF(INDEX(Квартиры!$I$2:$I$1501,MATCH($A10*1000+9,Квартиры!$K$2:$K$1501,0))>0," +У","")&IF(INDEX(Квартиры!$J$2:$J$1501,MATCH($A10*1000+9,Квартиры!$K$2:$K$1501,0))>0," +Г",""),"-")) | L10: =IF($A10="","",IFERROR(IF(Настройки!$B$4="да",INDEX(Квартиры!$D$2:$D$1501,MATCH($A10*1000+10,Квартиры!$K$2:$K$1501,0))&" / ","")&INDEX(Квартиры!$H$2:$H$1501,MATCH($A10*1000+10,Квартиры!$K$2:$K$1501,0))&" СУ"&IF(INDEX(Квартиры!$I$2:$I$1501,MATCH($A10*1000+10,Квартиры!$K$2:$K$1501,0))>0," +У","")&IF(INDEX(Квартиры!$J$2:$J$1501,MATCH($A10*1000+10,Квартиры!$K$2:$K$1501,0))>0," +Г",""),"-")) | M10: =IF($A10="","",IFERROR(IF(Настройки!$B$4="да",INDEX(Квартиры!$D$2:$D$1501,MATCH($A10*1000+11,Квартиры!$K$2:$K$1501,0))&" / ","")&INDEX(Квартиры!$H$2:$H$1501,MATCH($A10*1000+11,Квартиры!$K$2:$K$1501,0))&" СУ"&IF(INDEX(Квартиры!$I$2:$I$1501,MATCH($A10*1000+11,Квартиры!$K$2:$K$1501,0))>0," +У","")&IF(INDEX(Квартиры!$J$2:$J$1501,MATCH($A10*1000+11,Квартиры!$K$2:$K$1501,0))>0," +Г",""),"-")) | N10: =IF($A10="","",IFERROR(IF(Настройки!$B$4="да",INDEX(Квартиры!$D$2:$D$1501,MATCH($A10*1000+12,Квартиры!$K$2:$K$1501,0))&" / ","")&INDEX(Квартиры!$H$2:$H$1501,MATCH($A10*1000+12,Квартиры!$K$2:$K$1501,0))&" СУ"&IF(INDEX(Квартиры!$I$2:$I$1501,MATCH($A10*1000+12,Квартиры!$K$2:$K$1501,0))>0," +У","")&IF(INDEX(Квартиры!$J$2:$J$1501,MATCH($A10*1000+12,Квартиры!$K$2:$K$1501,0))>0," +Г",""),"-")) | O10: =IF($A10="","",IFERROR(IF(Настройки!$B$4="да",INDEX(Квартиры!$D$2:$D$1501,MATCH($A10*1000+13,Квартиры!$K$2:$K$1501,0))&" / ","")&INDEX(Квартиры!$H$2:$H$1501,MATCH($A10*1000+13,Квартиры!$K$2:$K$1501,0))&" СУ"&IF(INDEX(Квартиры!$I$2:$I$1501,MATCH($A10*1000+13,Квартиры!$K$2:$K$1501,0))>0," +У","")&IF(INDEX(Квартиры!$J$2:$J$1501,MATCH($A10*1000+13,Квартиры!$K$2:$K$1501,0))>0," +Г",""),"-")) | P10: =IF($A10="","",IFERROR(IF(Настройки!$B$4="да",INDEX(Квартиры!$D$2:$D$1501,MATCH($A10*1000+14,Квартиры!$K$2:$K$1501,0))&" / ","")&INDEX(Квартиры!$H$2:$H$1501,MATCH($A10*1000+14,Квартиры!$K$2:$K$1501,0))&" СУ"&IF(INDEX(Квартиры!$I$2:$I$1501,MATCH($A10*1000+14,Квартиры!$K$2:$K$1501,0))>0," +У","")&IF(INDEX(Квартиры!$J$2:$J$1501,MATCH($A10*1000+14,Квартиры!$K$2:$K$1501,0))>0," +Г",""),"-")) | Q10: =IF($A10="","",IFERROR(IF(Настройки!$B$4="да",INDEX(Квартиры!$D$2:$D$1501,MATCH($A10*1000+15,Квартиры!$K$2:$K$1501,0))&" / ","")&INDEX(Квартиры!$H$2:$H$1501,MATCH($A10*1000+15,Квартиры!$K$2:$K$1501,0))&" СУ"&IF(INDEX(Квартиры!$I$2:$I$1501,MATCH($A10*1000+15,Квартиры!$K$2:$K$1501,0))>0," +У","")&IF(INDEX(Квартиры!$J$2:$J$1501,MATCH($A10*1000+15,Квартиры!$K$2:$K$1501,0))>0," +Г",""),"-")) | R10: =IF(A10="","",C10&"|"&D10&"|"&E10&"|"&F10&"|"&G10&"|"&H10&"|"&I10&"|"&J10&"|"&K10&"|"&L10&"|"&M10&"|"&N10&"|"&O10&"|"&P10&"|"&Q10) | S10: =IF(A10="","",IFERROR(LOOKUP(2,1/(B$2:B9=B10),S$2:S9)&", ","")&A10) | U10: =IF(8>MAX(B$3:B$82),"",8) | V10: =IF(U10="","",LOOKUP(2,1/(B$3:B$82=U10),S$3:S$82)) | W10: =IF(U10="","",COUNTIF(B$3:B$82,U10))
A11: =IFERROR(IF(A10="","",SMALL(Квартиры!$B$2:$B$1501,COUNTIF(Квартиры!$B$2:$B$1501,"<="&A10)+1)),"") | B11: =IF(A11="","",IF(COUNTIF(R$2:R10,R11)=0,MAX(B$2:B10)+1,INDEX(B$2:B10,MATCH(R11,R$2:R10,0)))) | C11: =IF($A11="","",IFERROR(IF(Настройки!$B$4="да",INDEX(Квартиры!$D$2:$D$1501,MATCH($A11*1000+1,Квартиры!$K$2:$K$1501,0))&" / ","")&INDEX(Квартиры!$H$2:$H$1501,MATCH($A11*1000+1,Квартиры!$K$2:$K$1501,0))&" СУ"&IF(INDEX(Квартиры!$I$2:$I$1501,MATCH($A11*1000+1,Квартиры!$K$2:$K$1501,0))>0," +У","")&IF(INDEX(Квартиры!$J$2:$J$1501,MATCH($A11*1000+1,Квартиры!$K$2:$K$1501,0))>0," +Г",""),"-")) | D11: =IF($A11="","",IFERROR(IF(Настройки!$B$4="да",INDEX(Квартиры!$D$2:$D$1501,MATCH($A11*1000+2,Квартиры!$K$2:$K$1501,0))&" / ","")&INDEX(Квартиры!$H$2:$H$1501,MATCH($A11*1000+2,Квартиры!$K$2:$K$1501,0))&" СУ"&IF(INDEX(Квартиры!$I$2:$I$1501,MATCH($A11*1000+2,Квартиры!$K$2:$K$1501,0))>0," +У","")&IF(INDEX(Квартиры!$J$2:$J$1501,MATCH($A11*1000+2,Квартиры!$K$2:$K$1501,0))>0," +Г",""),"-")) | E11: =IF($A11="","",IFERROR(IF(Настройки!$B$4="да",INDEX(Квартиры!$D$2:$D$1501,MATCH($A11*1000+3,Квартиры!$K$2:$K$1501,0))&" / ","")&INDEX(Квартиры!$H$2:$H$1501,MATCH($A11*1000+3,Квартиры!$K$2:$K$1501,0))&" СУ"&IF(INDEX(Квартиры!$I$2:$I$1501,MATCH($A11*1000+3,Квартиры!$K$2:$K$1501,0))>0," +У","")&IF(INDEX(Квартиры!$J$2:$J$1501,MATCH($A11*1000+3,Квартиры!$K$2:$K$1501,0))>0," +Г",""),"-")) | F11: =IF($A11="","",IFERROR(IF(Настройки!$B$4="да",INDEX(Квартиры!$D$2:$D$1501,MATCH($A11*1000+4,Квартиры!$K$2:$K$1501,0))&" / ","")&INDEX(Квартиры!$H$2:$H$1501,MATCH($A11*1000+4,Квартиры!$K$2:$K$1501,0))&" СУ"&IF(INDEX(Квартиры!$I$2:$I$1501,MATCH($A11*1000+4,Квартиры!$K$2:$K$1501,0))>0," +У","")&IF(INDEX(Квартиры!$J$2:$J$1501,MATCH($A11*1000+4,Квартиры!$K$2:$K$1501,0))>0," +Г",""),"-")) | G11: =IF($A11="","",IFERROR(IF(Настройки!$B$4="да",INDEX(Квартиры!$D$2:$D$1501,MATCH($A11*1000+5,Квартиры!$K$2:$K$1501,0))&" / ","")&INDEX(Квартиры!$H$2:$H$1501,MATCH($A11*1000+5,Квартиры!$K$2:$K$1501,0))&" СУ"&IF(INDEX(Квартиры!$I$2:$I$1501,MATCH($A11*1000+5,Квартиры!$K$2:$K$1501,0))>0," +У","")&IF(INDEX(Квартиры!$J$2:$J$1501,MATCH($A11*1000+5,Квартиры!$K$2:$K$1501,0))>0," +Г",""),"-")) | H11: =IF($A11="","",IFERROR(IF(Настройки!$B$4="да",INDEX(Квартиры!$D$2:$D$1501,MATCH($A11*1000+6,Квартиры!$K$2:$K$1501,0))&" / ","")&INDEX(Квартиры!$H$2:$H$1501,MATCH($A11*1000+6,Квартиры!$K$2:$K$1501,0))&" СУ"&IF(INDEX(Квартиры!$I$2:$I$1501,MATCH($A11*1000+6,Квартиры!$K$2:$K$1501,0))>0," +У","")&IF(INDEX(Квартиры!$J$2:$J$1501,MATCH($A11*1000+6,Квартиры!$K$2:$K$1501,0))>0," +Г",""),"-")) | I11: =IF($A11="","",IFERROR(IF(Настройки!$B$4="да",INDEX(Квартиры!$D$2:$D$1501,MATCH($A11*1000+7,Квартиры!$K$2:$K$1501,0))&" / ","")&INDEX(Квартиры!$H$2:$H$1501,MATCH($A11*1000+7,Квартиры!$K$2:$K$1501,0))&" СУ"&IF(INDEX(Квартиры!$I$2:$I$1501,MATCH($A11*1000+7,Квартиры!$K$2:$K$1501,0))>0," +У","")&IF(INDEX(Квартиры!$J$2:$J$1501,MATCH($A11*1000+7,Квартиры!$K$2:$K$1501,0))>0," +Г",""),"-")) | J11: =IF($A11="","",IFERROR(IF(Настройки!$B$4="да",INDEX(Квартиры!$D$2:$D$1501,MATCH($A11*1000+8,Квартиры!$K$2:$K$1501,0))&" / ","")&INDEX(Квартиры!$H$2:$H$1501,MATCH($A11*1000+8,Квартиры!$K$2:$K$1501,0))&" СУ"&IF(INDEX(Квартиры!$I$2:$I$1501,MATCH($A11*1000+8,Квартиры!$K$2:$K$1501,0))>0," +У","")&IF(INDEX(Квартиры!$J$2:$J$1501,MATCH($A11*1000+8,Квартиры!$K$2:$K$1501,0))>0," +Г",""),"-")) | K11: =IF($A11="","",IFERROR(IF(Настройки!$B$4="да",INDEX(Квартиры!$D$2:$D$1501,MATCH($A11*1000+9,Квартиры!$K$2:$K$1501,0))&" / ","")&INDEX(Квартиры!$H$2:$H$1501,MATCH($A11*1000+9,Квартиры!$K$2:$K$1501,0))&" СУ"&IF(INDEX(Квартиры!$I$2:$I$1501,MATCH($A11*1000+9,Квартиры!$K$2:$K$1501,0))>0," +У","")&IF(INDEX(Квартиры!$J$2:$J$1501,MATCH($A11*1000+9,Квартиры!$K$2:$K$1501,0))>0," +Г",""),"-")) | L11: =IF($A11="","",IFERROR(IF(Настройки!$B$4="да",INDEX(Квартиры!$D$2:$D$1501,MATCH($A11*1000+10,Квартиры!$K$2:$K$1501,0))&" / ","")&INDEX(Квартиры!$H$2:$H$1501,MATCH($A11*1000+10,Квартиры!$K$2:$K$1501,0))&" СУ"&IF(INDEX(Квартиры!$I$2:$I$1501,MATCH($A11*1000+10,Квартиры!$K$2:$K$1501,0))>0," +У","")&IF(INDEX(Квартиры!$J$2:$J$1501,MATCH($A11*1000+10,Квартиры!$K$2:$K$1501,0))>0," +Г",""),"-")) | M11: =IF($A11="","",IFERROR(IF(Настройки!$B$4="да",INDEX(Квартиры!$D$2:$D$1501,MATCH($A11*1000+11,Квартиры!$K$2:$K$1501,0))&" / ","")&INDEX(Квартиры!$H$2:$H$1501,MATCH($A11*1000+11,Квартиры!$K$2:$K$1501,0))&" СУ"&IF(INDEX(Квартиры!$I$2:$I$1501,MATCH($A11*1000+11,Квартиры!$K$2:$K$1501,0))>0," +У","")&IF(INDEX(Квартиры!$J$2:$J$1501,MATCH($A11*1000+11,Квартиры!$K$2:$K$1501,0))>0," +Г",""),"-")) | N11: =IF($A11="","",IFERROR(IF(Настройки!$B$4="да",INDEX(Квартиры!$D$2:$D$1501,MATCH($A11*1000+12,Квартиры!$K$2:$K$1501,0))&" / ","")&INDEX(Квартиры!$H$2:$H$1501,MATCH($A11*1000+12,Квартиры!$K$2:$K$1501,0))&" СУ"&IF(INDEX(Квартиры!$I$2:$I$1501,MATCH($A11*1000+12,Квартиры!$K$2:$K$1501,0))>0," +У","")&IF(INDEX(Квартиры!$J$2:$J$1501,MATCH($A11*1000+12,Квартиры!$K$2:$K$1501,0))>0," +Г",""),"-")) | O11: =IF($A11="","",IFERROR(IF(Настройки!$B$4="да",INDEX(Квартиры!$D$2:$D$1501,MATCH($A11*1000+13,Квартиры!$K$2:$K$1501,0))&" / ","")&INDEX(Квартиры!$H$2:$H$1501,MATCH($A11*1000+13,Квартиры!$K$2:$K$1501,0))&" СУ"&IF(INDEX(Квартиры!$I$2:$I$1501,MATCH($A11*1000+13,Квартиры!$K$2:$K$1501,0))>0," +У","")&IF(INDEX(Квартиры!$J$2:$J$1501,MATCH($A11*1000+13,Квартиры!$K$2:$K$1501,0))>0," +Г",""),"-")) | P11: =IF($A11="","",IFERROR(IF(Настройки!$B$4="да",INDEX(Квартиры!$D$2:$D$1501,MATCH($A11*1000+14,Квартиры!$K$2:$K$1501,0))&" / ","")&INDEX(Квартиры!$H$2:$H$1501,MATCH($A11*1000+14,Квартиры!$K$2:$K$1501,0))&" СУ"&IF(INDEX(Квартиры!$I$2:$I$1501,MATCH($A11*1000+14,Квартиры!$K$2:$K$1501,0))>0," +У","")&IF(INDEX(Квартиры!$J$2:$J$1501,MATCH($A11*1000+14,Квартиры!$K$2:$K$1501,0))>0," +Г",""),"-")) | Q11: =IF($A11="","",IFERROR(IF(Настройки!$B$4="да",INDEX(Квартиры!$D$2:$D$1501,MATCH($A11*1000+15,Квартиры!$K$2:$K$1501,0))&" / ","")&INDEX(Квартиры!$H$2:$H$1501,MATCH($A11*1000+15,Квартиры!$K$2:$K$1501,0))&" СУ"&IF(INDEX(Квартиры!$I$2:$I$1501,MATCH($A11*1000+15,Квартиры!$K$2:$K$1501,0))>0," +У","")&IF(INDEX(Квартиры!$J$2:$J$1501,MATCH($A11*1000+15,Квартиры!$K$2:$K$1501,0))>0," +Г",""),"-")) | R11: =IF(A11="","",C11&"|"&D11&"|"&E11&"|"&F11&"|"&G11&"|"&H11&"|"&I11&"|"&J11&"|"&K11&"|"&L11&"|"&M11&"|"&N11&"|"&O11&"|"&P11&"|"&Q11) | S11: =IF(A11="","",IFERROR(LOOKUP(2,1/(B$2:B10=B11),S$2:S10)&", ","")&A11) | U11: =IF(9>MAX(B$3:B$82),"",9) | V11: =IF(U11="","",LOOKUP(2,1/(B$3:B$82=U11),S$3:S$82)) | W11: =IF(U11="","",COUNTIF(B$3:B$82,U11))
